Workbook

Sheet Manufacturing
A1: ProdOrder_ID | B1: Plant_Code | C1: Plant_Description | D1: Material_Code | E1: Material_Name | F1: Planned_Quantity (MT) | G1: Actual_Quantity (MT) | H1: Yield (%) | I1: Std_Cost_per_MT ($) | J1: Actual_Cost_per_MT ($) | K1: Total_Actual_Cost ($) | L1: Posting_Date | M1: Year | N1: Month | O1: Category
A2: PO5000 | B2: CN01 | C2: Shanghai, China | D2: SKU-ECOP-144 | E2: EcoPack | F2: 2755 | G2: 2493 | H2: 90.5 | I2: 1095.89 | J2: 1059.15 | K2: 2640461 | L2: 45762 | M2: 2025 | N2: 4 | O2: Packaging Materials
A3: PO5001 | B3: DE01 | C3: Frankfurt, Germany | D3: SKU-DURO-110 | E3: DuronBio | F3: 957 | G3: 1002 | H3: 104.7 | I3: 1955.9 | J3: 2179.62 | K3: 2183979.2 | L3: 45895 | M3: 2025 | N3: 8 | O3: Specialty Polymers
A4: PO5002 | B4: US01 | C4: Houston, USA | D4: SKU-GREE-349 | E4: GreenFoam | F4: 1423 | G4: 1389 | H4: 97.6 | I4: 1585.18 | J4: 1486.98 | K4: 2065415.2 | L4: 45892 | M4: 2025 | N4: 8 | O4: Consumer & Home Care
A5: PO5003 | B5: US01 | C5: Houston, USA | D5: SKU-GREE-494 | E5: GreenBond | F5: 2602 | G5: 2465 | H5: 94.7 | I5: 1999.15 | J5: 1804.68 | K5: 4448536.2 | L5: 45931 | M5: 2025 | N5: 10 | O5: Specialty Polymers
A6: PO5004 | B6: BR01 | C6: São Paulo, Brazil | D6: SKU-FLEX-294 | E6: FlexiChem | F6: 2649 | G6: 2315 | H6: 87.4 | I6: 1309.67 | J6: 1511.79 | K6: 3499793.9 | L6: 45815 | M6: 2025 | N6: 6 | O6: Specialty Polymers
A7: PO5005 | B7: IN01 | C7: Mumbai, India | D7: SKU-GREE-357 | E7: GreenFuel | F7: 2426 | G7: 2452 | H7: 101.1 | I7: 1909.02 | J7: 1982.55 | K7: 4861212.6 | L7: 45792 | M7: 2025 | N7: 5 | O7: Automotive Solutions
A8: PO5006 | B8: DE01 | C8: Frankfurt, Germany | D8: SKU-GREE-043 | E8: GreenFoam | F8: 904 | G8: 824 | H8: 91.2 | I8: 1170.34 | J8: 1315.64 | K8: 1084087.4 | L8: 45865 | M8: 2025 | N8: 7 | O8: Consumer & Home Care
A9: PO5007 | B9: IN01 | C9: Mumbai, India | D9: SKU-GREE-071 | E9: GreenBond | F9: 2062 | G9: 2021 | H9: 98 | I9: 1006.61 | J9: 1146.85 | K9: 2317783.9 | L9: 45807 | M9: 2025 | N9: 5 | O9: Specialty Polymers
A10: PO5008 | B10: DE01 | C10: Frankfurt, Germany | D10: SKU-POLY-000 | E10: PolyBio | F10: 2146 | G10: 2158 | H10: 100.6 | I10: 1475.44 | J10: 1393 | K10: 3006094 | L10: 45673 | M10: 2025 | N10: 1 | O10: Specialty Polymers
A11: PO5009 | B11: DE01 | C11: Frankfurt, Germany | D11: SKU-PACK-735 | E11: PackNatur | F11: 983 | G11: 839 | H11: 85.4 | I11: 1272.52 | J11: 1428.24 | K11: 1198293.4 | L11: 46014 | M11: 2025 | N11: 12 | O11: Packaging Materials
A12: PO5010 | B12: IN01 | C12: Mumbai, India | D12: SKU-HOME-465 | E12: HomePure | F12: 1761 | G12: 1718 | H12: 97.6 | I12: 1849.42 | J12: 1769.5 | K12: 3040001 | L12: 45932 | M12: 2025 | N12: 10 | O12: Consumer & Home Care
A13: PO5011 | B13: DE01 | C13: Frankfurt, Germany | D13: SKU-HOME-565 | E13: HomePure | F13: 1129 | G13: 1001 | H13: 88.7 | I13: 1805.78 | J13: 1770.93 | K13: 1772700.9 | L13: 45702 | M13: 2025 | N13: 2 | O13: Consumer & Home Care
... A2580: PO7578 | B2580: US01 | C2580: Houston, USA | D2580: SKU-BIOB-384 | E2580: BioBox | F2580: 850 | G2580: 761 | H2580: 89.5 | I2580: 1620.77 | J2580: 1669.01 | K2580: 1270116.6 | L2580: 45744 | M2580: 2025 | N2580: 3 | O2580: Packaging Materials

Sheet Sales Pipeline
A1: SalesOpp_ID | B1: Account_Name | C1: Region | D1: Stage | E1: Close_Date | F1: Year | G1: Month | H1: Product_Interest | I1: Est_Value ($M) | J1: Probability (%) | K1: Linked_Project_ID | L1: Category_Interest | M1: Weighted_Revenue ($)
A2: SO3000 | B2: GlobalGlobal SA | C2: Asia-Pacific | D2: Negotiation | E2: 45711 | F2: =YEAR(E2) -> 2025 | G2: =MONTH(E2) -> 2 | H2: GreenWrap | I2: 10 | J2: 80 | L2: {=XLOOKUP(H2,'Product Master'!B:B,'Product Master'!C:C)} -> Packaging Materials | M2: =I2*1000000*J2/100 -> 8000000
A3: SO3001 | B3: BioSolutions Corp | C3: North America | D3: Closed-Won | E3: 46316 | F3: =YEAR(E3) -> 2026 | G3: =MONTH(E3) -> 10 | H3: BioMold | I3: 29.8 | J3: 100 | L3: {=XLOOKUP(H3,'Product Master'!B:B,'Product Master'!C:C)} -> Specialty Polymers | M3: =I3*1000000*J3/100 -> 29800000
A4: SO3002 | B4: IndusSystems Ltd | C4: Asia-Pacific | D4: Negotiation | E4: 46140 | F4: =YEAR(E4) -> 2026 | G4: =MONTH(E4) -> 4 | H4: PureClean | I4: 75 | J4: 80 | L4: {=XLOOKUP(H4,'Product Master'!B:B,'Product Master'!C:C)} -> Consumer & Home Care | M4: =I4*1000000*J4/100 -> 60000000
A5: SO3003 | B5: AutoGlobal GmbH | C5: Europe-Middle East-Africa | D5: Closed-Lost | E5: 46453 | F5: =YEAR(E5) -> 2027 | G5: =MONTH(E5) -> 3 | H5: PlantGuard | I5: 56.9 | J5: 0 | L5: {=XLOOKUP(H5,'Product Master'!B:B,'Product Master'!C:C)} -> Industrial Lubricants | M5: =I5*1000000*J5/100 -> 0
A6: SO3004 | B6: IndusGlobal LLC | C6: South America | D6: Proposal Sent | E6: 45855 | F6: =YEAR(E6) -> 2025 | G6: =MONTH(E6) -> 7 | H6: PolyBio | I6: 50.8 | J6: 60 | L6: {=XLOOKUP(H6,'Product Master'!B:B,'Product Master'!C:C)} -> Specialty Polymers | M6: =I6*1000000*J6/100 -> 30480000
A7: SO3005 | B7: IndusSystems Ltd | C7: North America | D7: Prospecting | E7: 46809 | F7: =YEAR(E7) -> 2028 | G7: =MONTH(E7) -> 2 | H7: CareFlex | I7: 64.7 | J7: 20 | K7: RD0104 | L7: {=XLOOKUP(H7,'Product Master'!B:B,'Product Master'!C:C)} -> Consumer & Home Care | M7: =I7*1000000*J7/100 -> 12940000
A8: SO3006 | B8: PolyMaterials GmbH | C8: South America | D8: Negotiation | E8: 46753 | F8: =YEAR(E8) -> 2028 | G8: =MONTH(E8) -> 1 | H8: PureClean | I8: 28.6 | J8: 80 | L8: {=XLOOKUP(H8,'Product Master'!B:B,'Product Master'!C:C)} -> Consumer & Home Care | M8: =I8*1000000*J8/100 -> 22880000
A9: SO3007 | B9: GlobalMaterials SAS | C9: North America | D9: Closed-Lost | E9: 46600 | F9: =YEAR(E9) -> 2027 | G9: =MONTH(E9) -> 8 | H9: EcoDrive | I9: 58.3 | J9: 0 | L9: {=XLOOKUP(H9,'Product Master'!B:B,'Product Master'!C:C)} -> Automotive Solutions | M9: =I9*1000000*J9/100 -> 0
A10: SO3008 | B10: TransSolutions LLC | C10: Europe-Middle East-Africa | D10: Closed-Won | E10: 46842 | F10: =YEAR(E10) -> 2028 | G10: =MONTH(E10) -> 3 | H10: CareFlex | I10: 10.6 | J10: 100 | L10: {=XLOOKUP(H10,'Product Master'!B:B,'Product Master'!C:C)} -> Consumer & Home Care | M10: =I10*1000000*J10/100 -> 10600000
A11: SO3009 | B11: TransSystems Corp | C11: Europe-Middle East-Africa | D11: Negotiation | E11: 45694 | F11: =YEAR(E11) -> 2025 | G11: =MONTH(E11) -> 2 | H11: DuronBio | I11: 15.3 | J11: 80 | L11: {=XLOOKUP(H11,'Product Master'!B:B,'Product Master'!C:C)} -> Specialty Polymers | M11: =I11*1000000*J11/100 -> 12240000
A12: SO3010 | B12: PolyTech Corp | C12: Europe-Middle East-Africa | D12: Negotiation | E12: 45818 | F12: =YEAR(E12) -> 2025 | G12: =MONTH(E12) -> 6 | H12: PureClean | I12: 26 | J12: 80 | L12: {=XLOOKUP(H12,'Product Master'!B:B,'Product Master'!C:C)} -> Consumer & Home Care | M12: =I12*1000000*J12/100 -> 20800000
A13: SO3011 | B13: ChemTech SAS | C13: North America | D13: Negotiation | E13: 46525 | F13: =YEAR(E13) -> 2027 | G13: =MONTH(E13) -> 5 | H13: PackNatur | I13: 53.7 | J13: 80 | L13: {=XLOOKUP(H13,'Product Master'!B:B,'Product Master'!C:C)} -> Packaging Materials | M13: =I13*1000000*J13/100 -> 42960000
A14: SO3012 | B14: AutoGlobal BV | C14: Europe-Middle East-Africa | D14: Closed-Won | E14: 46461 | F14: =YEAR(E14) -> 2027 | G14: =MONTH(E14) -> 3 | H14: EcoFilm | I14: 78.8 | J14: 100 | L14: {=XLOOKUP(H14,'Product Master'!B:B,'Product Master'!C:C)} -> Packaging Materials | M14: =I14*1000000*J14/100 -> 78800000
A15: SO3013 | B15: IndusSolutions BV | C15: North America | D15: Proposal Sent | E15: 46788 | F15: =YEAR(E15) -> 2028 | G15: =MONTH(E15) -> 2 | H15: DriveFlex | I15: 9.2 | J15: 60 | L15: {=XLOOKUP(H15,'Product Master'!B:B,'Product Master'!C:C)} -> Automotive Solutions | M15: =I15*1000000*J15/100 -> 5520000
A16: SO3014 | B16: AutoSolutions Corp | C16: North America | D16: Negotiation | E16: 46636 | F16: =YEAR(E16) -> 2027 | G16: =MONTH(E16) -> 9 | H16: CarboLite | I16: 73.9 | J16: 80 | L16: {=XLOOKUP(H16,'Product Master'!B:B,'Product Master'!C:C)} -> Automotive Solutions | M16: =I16*1000000*J16/100 -> 59120000
A17: SO3015 | B17: IndusGlobal LLC | C17: Europe-Middle East-Africa | D17: Proposal Sent | E17: 46194 | F17: =YEAR(E17) -> 2026 | G17: =MONTH(E17) -> 6 | H17: StrongBio | I17: 58.7 | J17: 60 | L17: {=XLOOKUP(H17,'Product Master'!B:B,'Product Master'!C:C)} -> Specialty Polymers | M17: =I17*1000000*J17/100 -> 35220000
A18: SO3016 | B18: AutoSystems Inc | C18: North America | D18: Prospecting | E18: 46546 | F18: =YEAR(E18) -> 2027 | G18: =MONTH(E18) -> 6 | H18: StrongBio | I18: 17.2 | J18: 20 | L18: {=XLOOKUP(H18,'Product Master'!B:B,'Product Master'!C:C)} -> Specialty Polymers | M18: =I18*1000000*J18/100 -> 3440000
A19: SO3017 | B19: ChemSolutions Inc | C19: North America | D19: Prospecting | E19: 45756 | F19: =YEAR(E19) -> 2025 | G19: =MONTH(E19) -> 4 | H19: BioMold | I19: 6.6 | J19: 20 | L19: {=XLOOKUP(H19,'Product Master'!B:B,'Product Master'!C:C)} -> Specialty Polymers | M19: =I19*1000000*J19/100 -> 1320000
... A26: SO3024 | B26: AutoGlobal Corp | C26: Europe-Middle East-Africa | D26: Closed-Won | E26: 46829 | F26: =YEAR(E26) -> 2028 | G26: =MONTH(E26) -> 3 | H26: GreenFoam | I26: 15.1 | J26: 100 | L26: {=XLOOKUP(H26,'Product Master'!B:B,'Product Master'!C:C)} -> Consumer & Home Care | M26: =I26*1000000*J26/100 -> 15100000
A27: SO3025 | B27: NaturSolutions SA | C27: South America | D27: Negotiation | E27: 45849 | F27: =YEAR(E27) -> 2025 | G27: =MONTH(E27) -> 7 | H27: PolyBio | I27: 31.6 | J27: 80 | K27: RD0190 | L27: {=XLOOKUP(H27,'Product Master'!B:B,'Product Master'!C:C)} -> Specialty Polymers | M27: =I27*1000000*J27/100 -> 25280000
A28: SO3026 | B28: PackMaterials Inc | C28: North America | D28: Negotiation | E28: 46460 | F28: =YEAR(E28) -> 2027 | G28: =MONTH(E28) -> 3 | H28: CleanWave | I28: 64.2 | J28: 80 | L28: {=XLOOKUP(H28,'Product Master'!B:B,'Product Master'!C:C)} -> Consumer & Home Care | M28: =I28*1000000*J28/100 -> 51360000
A29: SO3027 | B29: PolyTech Ltd | C29: South America | D29: Closed-Lost | E29: 46832 | F29: =YEAR(E29) -> 2028 | G29: =MONTH(E29) -> 3 | H29: HomePure | I29: 72.8 | J29: 0 | L29: {=XLOOKUP(H29,'Product Master'!B:B,'Product Master'!C:C)} -> Consumer & Home Care | M29: =I29*1000000*J29/100 -> 0
A30: SO3028 | B30: GlobalSystems SA | C30: North America | D30: Proposal Sent | E30: 46077 | F30: =YEAR(E30) -> 2026 | G30: =MONTH(E30) -> 2 | H30: PureClean | I30: 65.3 | J30: 60 | K30: RD0061 | L30: {=XLOOKUP(H30,'Product Master'!B:B,'Product Master'!C:C)} -> Consumer & Home Care | M30: =I30*1000000*J30/100 -> 39180000
A31: SO3029 | B31: TransSolutions Group | C31: South America | D31: Closed-Won | E31: 46178 | F31: =YEAR(E31) -> 2026 | G31: =MONTH(E31) -> 6 | H31: FreshBio | I31: 56 | J31: 100 | L31: {=XLOOKUP(H31,'Product Master'!B:B,'Product Master'!C:C)} -> Consumer & Home Care | M31: =I31*1000000*J31/100 -> 56000000
A32: SO3030 | B32: EcoGlobal SAS | C32: Asia-Pacific | D32: Negotiation | E32: 46223 | F32: =YEAR(E32) -> 2026 | G32: =MONTH(E32) -> 7 | H32: EcoWash | I32: 75.5 | J32: 80 | L32: {=XLOOKUP(H32,'Product Master'!B:B,'Product Master'!C:C)} -> Consumer & Home Care | M32: =I32*1000000*J32/100 -> 60400000
A33: SO3031 | B33: TransGlobal Ltd | C33: Europe-Middle East-Africa | D33: Negotiation | E33: 46104 | F33: =YEAR(E33) -> 2026 | G33: =MONTH(E33) -> 3 | H33: CareFlex | I33: 75.6 | J33: 80 | L33: {=XLOOKUP(H33,'Product Master'!B:B,'Product Master'!C:C)} -> Consumer & Home Care | M33: =I33*1000000*J33/100 -> 60480000
A34: SO3032 | B34: NaturTech Group | C34: South America | D34: Proposal Sent | E34: 45721 | F34: =YEAR(E34) -> 2025 | G34: =MONTH(E34) -> 3 | H34: EcoDrive | I34: 69.1 | J34: 60 | L34: {=XLOOKUP(H34,'Product Master'!B:B,'Product Master'!C:C)} -> Automotive Solutions | M34: =I34*1000000*J34/100 -> 41460000
A35: SO3033 | B35: PolyMaterials PLC | C35: Asia-Pacific | D35: Proposal Sent | E35: 46089 | F35: =YEAR(E35) -> 2026 | G35: =MONTH(E35) -> 3 | H35: BioSeal | I35: 71.1 | J35: 60 | L35: {=XLOOKUP(H35,'Product Master'!B:B,'Product Master'!C:C)} -> Automotive Solutions | M35: =I35*1000000*J35/100 -> 42660000
A36: SO3034 | B36: NaturMaterials Inc | C36: Europe-Middle East-Africa | D36: Closed-Lost | E36: 46379 | F36: =YEAR(E36) -> 2026 | G36: =MONTH(E36) -> 12 | H36: EcoFilm | I36: 9 | J36: 0 | L36: {=XLOOKUP(H36,'Product Master'!B:B,'Product Master'!C:C)} -> Packaging Materials | M36: =I36*1000000*J36/100 -> 0
A37: SO3035 | B37: TransGlobal SAS | C37: South America | D37: Negotiation | E37: 46034 | F37: =YEAR(E37) -> 2026 | G37: =MONTH(E37) -> 1 | H37: GreenFoam | I37: 6.7 | J37: 80 | L37: {=XLOOKUP(H37,'Product Master'!B:B,'Product Master'!C:C)} -> Consumer & Home Care | M37: =I37*1000000*J37/100 -> 5360000
A38: SO3036 | B38: IndusGlobal GmbH | C38: North America | D38: Closed-Lost | E38: 45757 | F38: =YEAR(E38) -> 2025 | G38: =MONTH(E38) -> 4 | H38: EcoPack | I38: 61.5 | J38: 0 | L38: {=XLOOKUP(H38,'Product Master'!B:B,'Product Master'!C:C)} -> Packaging Materials | M38: =I38*1000000*J38/100 -> 0
A39: SO3037 | B39: PackTech Corp | C39: Europe-Middle East-Africa | D39: Proposal Sent | E39: 46161 | F39: =YEAR(E39) -> 2026 | G39: =MONTH(E39) -> 5 | H39: PolyLite | I39: 8.1 | J39: 60 | L39: {=XLOOKUP(H39,'Product Master'!B:B,'Product Master'!C:C)} -> Packaging Materials | M39: =I39*1000000*J39/100 -> 4860000
A40: SO3038 | B40: AutoTech Inc | C40: Europe-Middle East-Africa | D40: Negotiation | E40: 45811 | F40: =YEAR(E40) -> 2025 | G40: =MONTH(E40) -> 6 | H40: EcoPack | I40: 78.8 | J40: 80 | L40: {=XLOOKUP(H40,'Product Master'!B:B,'Product Master'!C:C)} -> Packaging Materials | M40: =I40*1000000*J40/100 -> 63040000
A41: SO3039 | B41: PolyGlobal SAS | C41: North America | D41: Prospecting | E41: 46777 | F41: =YEAR(E41) -> 2028 | G41: =MONTH(E41) -> 1 | H41: NaturPoly | I41: 51.7 | J41: 20 | L41: {=XLOOKUP(H41,'Product Master'!B:B,'Product Master'!C:C)} -> Specialty Polymers | M41: =I41*1000000*J41/100 -> 10340000
A42: SO3040 | B42: ChemTech LLC | C42: Asia-Pacific | D42: Closed-Lost | E42: 46275 | F42: =YEAR(E42) -> 2026 | G42: =MONTH(E42) -> 9 | H42: LubriGreen | I42: 28.7 | J42: 0 | L42: {=XLOOKUP(H42,'Product Master'!B:B,'Product Master'!C:C)} -> Industrial Lubricants | M42: =I42*1000000*J42/100 -> 0
... A47: SO3045 | B47: ChemTech GmbH | C47: North America | D47: Closed-Won | E47: 46576 | F47: =YEAR(E47) -> 2027 | G47: =MONTH(E47) -> 7 | H47: GreenFoam | I47: 11.8 | J47: 100 | L47: {=XLOOKUP(H47,'Product Master'!B:B,'Product Master'!C:C)} -> Consumer & Home Care | M47: =I47*1000000*J47/100 -> 11800000
A48: SO3046 | B48: BioMaterials Ltd | C48: North America | D48: Proposal Sent | E48: 46120 | F48: =YEAR(E48) -> 2026 | G48: =MONTH(E48) -> 4 | H48: AutoGuard | I48: 9.3 | J48: 60 | K48: RD0291 | L48: {=XLOOKUP(H48,'Product Master'!B:B,'Product Master'!C:C)} -> Automotive Solutions | M48: =I48*1000000*J48/100 -> 5580000
A49: SO3047 | B49: TransSystems Corp | C49: North America | D49: Negotiation | E49: 46800 | F49: =YEAR(E49) -> 2028 | G49: =MONTH(E49) -> 2 | H49: NaturShine | I49: 19.7 | J49: 80 | L49: {=XLOOKUP(H49,'Product Master'!B:B,'Product Master'!C:C)} -> Consumer & Home Care | M49: =I49*1000000*J49/100 -> 15760000
A50: SO3048 | B50: ChemSolutions BV | C50: North America | D50: Proposal Sent | E50: 45983 | F50: =YEAR(E50) -> 2025 | G50: =MONTH(E50) -> 11 | H50: CareFlex | I50: 29.2 | J50: 60 | L50: {=XLOOKUP(H50,'Product Master'!B:B,'Product Master'!C:C)} -> Consumer & Home Care | M50: =I50*1000000*J50/100 -> 17520000
...

Sheet Weighted Revenue by Categories
C2: =B2/$B$7 -> 0.21129475
C3: =B3/$B$7 -> 0.21353356
C4: =B4/$B$7 -> 0.20545148
C5: =B5/$B$7 -> 0.17906575
C6: =B6/$B$7 -> 0.19065446
C7: =B7/$B$7 -> 1
C12: =B12/$B$17 -> 0.21753595
C13: =B13/$B$17 -> 0.20276226
C14: =B14/$B$17 -> 0.20309199
C15: =B15/$B$17 -> 0.1820614
C16: =B16/$B$17 -> 0.1945484
C17: =B17/$B$17 -> 1

Sheet Supply Chain
A1: PO_Number | B1: Supplier_Name | C1: Material_Code | D1: RawMaterial_Name | E1: Qty (MT) | F1: Unit_Cost ($) | G1: Country_Origin | H1: Delivery_Date | I1: Delivery_Month | J1: Delivery_Yr | K1: On_Time (Y/N) | L1: CO2_Emissions (kg/MT) | M1: Total MT Cost ($) | N1: Total Emissions (kg)
A2: PUR2000 | B2: EcoMaterials Co. | C2: RM-0000 | D2: Sugarcane Fiber | E2: 669 | F2: 301.56 | G2: Germany | H2: 45838 | I2: 6 | J2: 2025 | K2: N | L2: 116.8 | M2: 201743.64 | N2: 78139.2
A3: PUR2001 | B3: NaturInput GmbH | C3: RM-0001 | D3: Palm Oil Derivative | E3: 820 | F3: 338.39 | G3: India | H3: 45870 | I3: 8 | J3: 2025 | K3: Y | L3: 492.6 | M3: 277479.8 | N3: 403932
A4: PUR2002 | B4: BioFeedstock Ltd. | C4: RM-0002 | D4: Algae Oil | E4: 514 | F4: 502.61 | G4: Germany | H4: 45969 | I4: 11 | J4: 2025 | K4: N | L4: 350.9 | M4: 258341.54 | N4: 180362.6
A5: PUR2003 | B5: PalmEco Corp | C5: RM-0003 | D5: Sugarcane Fiber | E5: 854 | F5: 450.71 | G5: China | H5: 45917 | I5: 9 | J5: 2025 | K5: Y | L5: 313.9 | M5: 384906.34 | N5: 268070.6
A6: PUR2004 | B6: AgroSource Intl. | C6: RM-0004 | D6: Algae Oil | E6: 120 | F6: 542.47 | G6: Indonesia | H6: 45766 | I6: 4 | J6: 2025 | K6: Y | L6: 283.5 | M6: 65096.4 | N6: 34020
A7: PUR2005 | B7: BioFeedstock Ltd. | C7: RM-0005 | D7: Algae Oil | E7: 211 | F7: 408 | G7: Malaysia | H7: 46015 | I7: 12 | J7: 2025 | K7: Y | L7: 322.6 | M7: 86088 | N7: 68068.6
A8: PUR2006 | B8: AgroSource Intl. | C8: RM-0006 | D8: Cassava Starch | E8: 218 | F8: 552.58 | G8: Malaysia | H8: 45987 | I8: 11 | J8: 2025 | K8: Y | L8: 295.8 | M8: 120462.44 | N8: 64484.4
A9: PUR2409 | B9: AgroSource Intl. | C9: RM-0409 | D9: Algae Oil | E9: 472 | F9: 522.8 | G9: Brazil | H9: 45986 | I9: 11 | J9: 2025 | K9: Y | L9: 391.6 | M9: 246761.6 | N9: 184835.2
A10: PUR2008 | B10: PalmEco Corp | C10: RM-0008 | D10: Cassava Starch | E10: 963 | F10: 389.65 | G10: India | H10: 46014 | I10: 12 | J10: 2025 | K10: Y | L10: 267.2 | M10: 375232.95 | N10: 257313.6
A11: PUR2009 | B11: AgroSource Intl. | C11: RM-0009 | D11: Sugarcane Fiber | E11: 770 | F11: 534.75 | G11: Malaysia | H11: 46011 | I11: 12 | J11: 2025 | K11: Y | L11: 387.7 | M11: 411757.5 | N11: 298529
A12: PUR2010 | B12: BioFeedstock Ltd. | C12: RM-0010 | D12: Corn Starch | E12: 637 | F12: 509.81 | G12: Indonesia | H12: 45781 | I12: 5 | J12: 2025 | K12: Y | L12: 419.9 | M12: 324748.97 | N12: 267476.3
A13: PUR2011 | B13: BioFeedstock Ltd. | C13: RM-0011 | D13: Algae Oil | E13: 523 | F13: 411.1 | G13: Indonesia | H13: 45927 | I13: 9 | J13: 2025 | K13: N | L13: 170 | M13: 215005.3 | N13: 88910
... A2891: PUR4889 | B2891: EcoMaterials Co. | C2891: RM-2889 | D2891: Wood Pulp | E2891: 118 | F2891: 402.01 | G2891: USA | H2891: 45723 | I2891: 3 | J2891: 2025 | K2891: N | L2891: 430.6 | M2891: 47437.18 | N2891: 50810.8

Sheet Total Qty by Suppliers

Sheet CO2 emissions avoided
A1: Algae Oil | O1: Interpret CO2 avoided formula
A2: Supplier_Name | B2: SUM of Qty (MT) | C2: AVERAGE of CO2_Emissions (kg/MT) | D2: AVERAGE of Unit_Cost ($) | F2: Algae Oil | G2: AgroSource Intl. | H2: BioFeedstock Ltd. | I2: EcoMaterials Co. | J2: GreenFibre BV | K2: NaturInput GmbH | L2: PalmEco Corp | M2: SustainSource Inc. | O2: Sign of value | P2: Situation | Q2: What it means
A3: AgroSource Intl. | B3: 25607 | C3: 320.03 | D3: 460.6764 | F3: AgroSource Intl. | G3: #DIV/0! | H3: 0.8 | I3: -1.92 | J3: -0.32 | K3: 0.39 | L3: 11.47 | M3: -1.84 | O3: Large pos | P3: Higher-cost but lower-CO₂ supplier | Q3: You pay more but get big CO₂ cuts → good trade-off if budget allows.
A4: BioFeedstock Ltd. | B4: 28895 | C4: 336.23 | D4: 440.32173 | F4: BioFeedstock Ltd. | G4: 0.8 | H4: #DIV/0! | I4: 2.6 | J4: 4.1 | K4: -12.81 | L4: 2.05 | M4: 1.86 | O4: Small pos (≈ 0-2) | P4: Slightly higher cost for small emission gain | Q4: Low priority.
A5: EcoMaterials Co. | B5: 35552 | C5: 304.39 | D5: 452.54902 | F5: EcoMaterials Co. | G5: -1.92 | H5: 2.6 | I5: #DIV/0! | J5: 1.52 | K5: 1.85 | L5: 1.43 | M5: -2.15 | O5: Negative and new cost < current cost | P5: Cheaper and cleaner supplier | Q5: Best case (profit + sustainability win).
A6: GreenFibre BV | B6: 41109 | C6: 315.14 | D6: 445.46132 | F6: GreenFibre BV | G6: -0.32 | H6: 4.1 | I6: 1.52 | J6: #DIV/0! | K6: 2.25 | L6: 1.47 | M6: 0.63 | O6: Negative and new cost > current cost | P6: Costlier and dirtier | Q6: Avoid.
A7: NaturInput GmbH | B7: 30881 | C7: 328.13 | D7: 439.68922 | F7: NaturInput GmbH | G7: 0.39 | H7: -12.81 | I7: 1.85 | J7: 2.25 | K7: #DIV/0! | L7: 1.66 | M7: 1.25
A8: PalmEco Corp | B8: 35884 | C8: 288.85 | D8: 463.39443 | F8: PalmEco Corp | G8: 11.47 | H8: 2.05 | I8: 1.43 | J8: 1.47 | K8: 1.66 | L8: #DIV/0! | M8: 2.38
A9: SustainSource Inc. | B9: 35101 | C9: 309.28 | D9: 454.82623 | F9: SustainSource Inc. | G9: -1.84 | H9: 1.86 | I9: -2.15 | J9: 0.63 | K9: 1.25 | L9: 2.38 | M9: #DIV/0!
A10: Grand Total | B10: 233029 | C10: 313.98 | D10: 450.86492
O12: Proposed Shift in Procurement (Short-Term Plan)
A13: Cassava | B13: SUM of Qty (MT) | C13: AVERAGE of CO2_Emissions (kg/MT) | D13: AVERAGE of Unit_Cost ($) | F13: Cassava | G13: AgroSource Intl. | H13: BioFeedstock Ltd. | I13: EcoMaterials Co. | J13: GreenFibre BV | K13: NaturInput GmbH | L13: PalmEco Corp | M13: SustainSource Inc. | O13: Raw Materials | P13: Supplier | Q13: Qty Current | R13: Unit_Cost Current | S13: CO2 Current | T13: Qty_Shifted | U13: Unit_Cost New | V13: CO2 New | W13: Change in Cost | X13: Change in Emission (kg) | Y13: Change in Emission (ton)
A14: AgroSource Intl. | B14: 37856 | C14: 300.3 | D14: 448.1788 | F14: AgroSource Intl. | G14: #DIV/0! | H14: 32.89 | I14: -0.89 | J14: 11.7 | K14: 1.7 | L14: 1.46 | M14: 0.08 | O14: Cassava | P14: AgroSource Intl. | Q14: =xlookup(P14,$B$82:$B$88,$C$82:$C$88) -> 37856 | R14: =xlookup(P14,$A$14:$A$20,$D$14:$D$20) -> 448.1788 | S14: =xlookup(P14,$A$3:$A$9,$C$3:$C$9) -> 320.03 | T14: =Q14*0.1 -> 3785.6 | U14: {=xlookup(I13,$A$14:$A$20,$D$14:$D$20)} -> 435.64735 | V14: {=xlookup(I13,$A$14:$A$20,$C$14:$C$20)} -> 289.1 | W14: =(R14-U14)*T14 -> 47439.069 | X14: =(S14-V14)*T14 -> 117088.61 | Y14: =X14/1000 -> 117.08861
A15: BioFeedstock Ltd. | B15: 30332 | C15: 319.62 | D15: 447.59151 | F15: BioFeedstock Ltd. | G15: 32.89 | H15: #DIV/0! | I15: -2.56 | J15: -19.18 | K15: 3.94 | L15: 0.64 | M15: 1.06 | O15: Cassava | P15: SustainSource Inc. | Q15: =xlookup(P15,$B$82:$B$88,$C$82:$C$88) -> 33086 | R15: =xlookup(P15,$A$14:$A$20,$D$14:$D$20) -> 467.21246 | S15: =xlookup(P15,$A$3:$A$9,$C$3:$C$9) -> 309.28 | T15: =Q15*0.1 -> 3308.6 | U15: {=xlookup(K13,$A$14:$A$20,$D$14:$D$20)} -> 455.7693 | V15: {=xlookup(K13,$A$14:$A$20,$C$14:$C$20)} -> 287.39 | W15: =(R15-U15)*T15 -> 37860.842 | X15: =(S15-V15)*T15 -> 72425.254 | Y15: =X15/1000 -> 72.425254
A16: EcoMaterials Co. | B16: 28208 | C16: 289.1 | D16: 435.64735 | F16: EcoMaterials Co. | G16: -0.89 | H16: -2.56 | I16: #DIV/0! | J16: -1.97 | K16: 0.09 | L16: 4.27 | M16: -0.31 | O16: Corn | P16: BioFeedstock Ltd. | Q16: =xlookup(P16,$B$89:$B$95,$C$89:$C$95) -> 37773 | R16: =xlookup(P16,$A$24:$A$30,$D$24:$D$30) -> 440.74942 | S16: =xlookup(P16,$A$14:$A$20,$C$14:$C$20) -> 319.62 | T16: =Q16*0.1 -> 3777.3 | U16: {=xlookup(I23,$A$14:$A$20,$D$14:$D$20)} -> 435.64735 | V16: {=xlookup(I23,$A$24:$A$30,$C$24:$C$30)} -> 272.74 | W16: =(R16-U16)*T16 -> 19272.062 | X16: =(S16-V16)*T16 -> 177079.82 | Y16: =X16/1000 -> 177.07982
A17: GreenFibre BV | B17: 31375 | C17: 311.89 | D17: 447.1883 | F17: GreenFibre BV | G17: 11.7 | H17: -19.18 | I17: -1.97 | J17: #DIV/0! | K17: 2.86 | L17: 1 | M17: 0.65 | O17: Corn | P17: NaturInput GmbH | Q17: =xlookup(P17,$B$89:$B$95,$C$89:$C$95) -> 36806 | R17: =xlookup(P17,$A$24:$A$30,$D$24:$D$30) -> 442.96548 | S17: =xlookup(P17,$A$14:$A$20,$C$14:$C$20) -> 287.39 | T17: =Q17*0.1 -> 3680.6 | U17: {=xlookup(I23,$A$14:$A$20,$D$14:$D$20)} -> 435.64735 | V17: {=xlookup(I23,$A$24:$A$30,$C$24:$C$30)} -> 272.74 | W17: =(R17-U17)*T17 -> 26935.135 | X17: =(S17-V17)*T17 -> 53920.79 | Y17: =X17/1000 -> 53.92079
A18: NaturInput GmbH | B18: 30714 | C18: 287.39 | D18: 455.7693 | F18: NaturInput GmbH | G18: 1.7 | H18: 3.94 | I18: 0.09 | J18: 2.86 | K18: #DIV/0! | L18: 1.52 | M18: -1 | O18: Palm | P18: AgroSource Intl. | Q18: =xlookup(P18,$B$96:$B$102,$C$96:$C$102) -> 36297 | R18: =xlookup(P18,$A$34:$A$40,$D$34:$D$40) -> 454.16554 | S18: =xlookup(P18,$A$34:$A$40,$C$34:$C$40) -> 299.52 | T18: =Q18*0.1 -> 3629.7 | U18: {=xlookup(I33,$A$34:$A$40,$D$34:$D$40)} -> 451.72102 | V18: {=xlookup(I33,$A$34:$A$40,$C$34:$C$40)} -> 281.79 | W18: =(R18-U18)*T18 -> 8872.8801 | X18: =(S18-V18)*T18 -> 64354.581 | Y18: =X18/1000 -> 64.354581
A19: PalmEco Corp | B19: 22978 | C19: 333.96 | D19: 425.13364 | F19: PalmEco Corp | G19: 1.46 | H19: 0.64 | I19: 4.27 | J19: 1 | K19: 1.52 | L19: #DIV/0! | M19: 0.83 | O19: Palm | P19: NaturInput GmbH | Q19: =xlookup(P19,$B$96:$B$102,$C$96:$C$102) -> 32317 | R19: =xlookup(P19,$A$34:$A$40,$D$34:$D$40) -> 442.60807 | S19: =xlookup(P19,$A$34:$A$40,$C$34:$C$40) -> 308.49 | T19: =Q19*0.1 -> 3231.7 | U19: {=xlookup(L33,$A$34:$A$40,$D$34:$D$40)} -> 432.02037 | V19: {=xlookup(L33,$A$34:$A$40,$C$34:$C$40)} -> 292.87 | W19: =(R19-U19)*T19 -> 34216.269 | X19: =(S19-V19)*T19 -> 50479.154 | Y19: =X19/1000 -> 50.479154
A20: SustainSource Inc. | B20: 33086 | C20: 298.85 | D20: 467.21246 | F20: SustainSource Inc. | G20: 0.08 | H20: 1.06 | I20: -0.31 | J20: 0.65 | K20: -1 | L20: 0.83 | M20: #DIV/0! | O20: Soy Protein | P20: GreenFibre BV | Q20: =xlookup(P20,$B$103:$B$109,$C$103:$C$109) -> 34020 | R20: =xlookup(P20,$A$44:$A$50,$D$44:$D$50) -> 480.43738 | S20: =xlookup(P20,$A$34:$A$40,$C$34:$C$40) -> 295.87 | T20: =Q20*0.1 -> 3402 | U20: {=xlookup(H43,$A$44:$A$50,$D$44:$D$50)} -> 474.79661 | V20: {=xlookup(H43,$A$44:$A$50,$C$44:$C$50)} -> 287.64 | W20: =(R20-U20)*T20 -> 19189.899 | X20: =(S20-V20)*T20 -> 27998.46 | Y20: =X20/1000 -> 27.99846
A21: Grand Total | B21: 214549 | C21: 304.76 | D21: 447.87793 | O21: Soy Protein | P21: PalmEco Corp | Q21: =xlookup(P21,$B$103:$B$109,$C$103:$C$109) -> 39277 | R21: =xlookup(P21,$A$44:$A$50,$D$44:$D$50) -> 445.27924 | S21: =xlookup(P21,$A$34:$A$40,$C$34:$C$40) -> 292.87 | T21: =Q21*0.1 -> 3927.7 | U21: {=xlookup(M43,$A$44:$A$50,$D$44:$D$50)} -> 434.42575 | V21: {=xlookup(M43,$A$44:$A$50,$C$44:$C$50)} -> 275.47 | W21: =(R21-U21)*T21 -> 42629.262 | X21: =(S21-V21)*T21 -> 68341.98 | Y21: =X21/1000 -> 68.34198
O22: Wood Pulp | P22: PalmEco Corp | Q22: {=xlookup(P22,$B$117:$B$123,$C$117:$C$123)} -> 42821 | R22: {=xlookup(P22,$A$54:$A$60,$D$54:$D$60)} -> 464.55 | S22: {=xlookup(P22,$A$54:$A$60,$C$54:$C$60)} -> 311.87 | T22: =Q22*0.1 -> 4282.1 | U22: {=xlookup(I63,$A$54:$A$60,$D$54:$D$60)} -> 459.58455 | V22: {=xlookup(I63,$A$54:$A$60,$C$54:$C$60)} -> 293.26 | W22: =(R22-U22)*T22 -> 21262.573 | X22: =(S22-V22)*T22 -> 79689.881 | Y22: =X22/1000 -> 79.689881
A23: Corn | B23: SUM of Qty (MT) | C23: AVERAGE of CO2_Emissions (kg/MT) | D23: AVERAGE of Unit_Cost ($) | F23: Corn | G23: AgroSource Intl. | H23: BioFeedstock Ltd. | I23: EcoMaterials Co. | J23: GreenFibre BV | K23: NaturInput GmbH | L23: PalmEco Corp | M23: SustainSource Inc.
A24: AgroSource Intl. | B24: 28646 | C24: 332.15 | D24: 438.16385 | F24: AgroSource Intl. | G24: #DIV/0! | H24: 1.31 | I24: -13.93 | J24: 2.1 | K24: 8.44 | L24: 1.12 | M24: -3.72
A25: BioFeedstock Ltd. | B25: 37773 | C25: 328.75 | D25: 440.74942 | F25: BioFeedstock Ltd. | G25: 1.31 | H25: #DIV/0! | I25: -8.17 | J25: 2.23 | K25: 16.75 | L25: 1.1 | M25: -1.85
A26: EcoMaterials Co. | B26: 29979 | C26: 272.74 | D26: 433.89846 | F26: EcoMaterials Co. | G26: -13.93 | H26: -8.17 | I26: #DIV/0! | J26: -0.85 | K26: -2.08 | L26: -0.68 | M26: 379.33
A27: GreenFibre BV | B27: 36908 | C27: 292.39 | D27: 457.05662 | F27: GreenFibre BV | G27: 2.1 | H27: 2.23 | I27: -0.85 | J27: #DIV/0! | K27: -0.05 | L27: -0.37 | M27: 1.01
A28: NaturInput GmbH | B28: 36806 | C28: 291.62 | D28: 442.96548 | F28: NaturInput GmbH | G28: 8.44 | H28: 16.75 | I28: -2.08 | J28: -0.05 | K28: #DIV/0! | L28: -0.2 | M28: 2.64
A29: PalmEco Corp | B29: 33522 | C29: 296.97 | D29: 469.57803 | F29: PalmEco Corp | G29: 1.12 | H29: 1.1 | I29: -0.68 | J29: -0.37 | K29: -0.2 | L29: #DIV/0! | M29: 0.53
A30: SustainSource Inc. | B30: 24504 | C30: 315.87 | D30: 433.78477 | F30: SustainSource Inc. | G30: -3.72 | H30: -1.85 | I30: 379.33 | J30: 1.01 | K30: 2.64 | L30: 0.53 | M30: #DIV/0!
A31: Grand Total | B31: 228138 | C31: 304.29 | D31: 446.0797
A33: Palm Oil | B33: SUM of Qty (MT) | C33: AVERAGE of CO2_Emissions (kg/MT) | D33: AVERAGE of Unit_Cost ($) | F33: Palm Oil | G33: AgroSource Intl. | H33: BioFeedstock Ltd. | I33: EcoMaterials Co. | J33: GreenFibre BV | K33: NaturInput GmbH | L33: PalmEco Corp | M33: SustainSource Inc.
A34: AgroSource Intl. | B34: 36297 | C34: 299.52 | D34: 454.16554 | F34: AgroSource Intl. | G34: #DIV/0! | H34: -2.91 | I34: -7.25 | J34: -0.39 | K34: 0.78 | L34: -0.3 | M34: 1.5
A35: BioFeedstock Ltd. | B35: 25308 | C35: 295.37 | D35: 452.74214 | F35: BioFeedstock Ltd. | G35: -2.91 | H35: #DIV/0! | I35: -13.3 | J35: 0.06 | K35: 1.29 | L35: -0.12 | M35: 2.79
A36: EcoMaterials Co. | B36: 29873 | C36: 281.79 | D36: 451.72102 | F36: EcoMaterials Co. | G36: -7.25 | H36: -13.3 | I36: #DIV/0! | J36: 2.07 | K36: 2.93 | L36: 0.56 | M36: 7.07
A37: GreenFibre BV | B37: 25798 | C37: 295.87 | D37: 444.91043 | F37: GreenFibre BV | G37: -0.39 | H37: 0.06 | I37: 2.07 | J37: #DIV/0! | K37: 5.48 | L37: -0.23 | M37: -4.39
A38: NaturInput GmbH | B38: 32317 | C38: 308.49 | D38: 442.60807 | F38: NaturInput GmbH | G38: 0.78 | H38: 1.29 | I38: 2.93 | J38: 5.48 | K38: #DIV/0! | L38: -1.48 | M38: -0.08
A39: PalmEco Corp | B39: 28358 | C39: 292.87 | D39: 432.02037 | F39: PalmEco Corp | G39: -0.3 | H39: -0.12 | I39: 0.56 | J39: -0.23 | K39: -1.48 | L39: #DIV/0! | M39: -1.01
A40: SustainSource Inc. | B40: 31175 | C40: 308.93 | D40: 447.88491 | F40: SustainSource Inc. | G40: 1.5 | H40: 2.79 | I40: 7.07 | J40: -4.39 | K40: -0.08 | L40: -1.01 | M40: #DIV/0!
A41: Grand Total | B41: 209126 | C41: 297.62 | D41: 446.67931
A43: Soy Protetin | B43: SUM of Qty (MT) | C43: AVERAGE of CO2_Emissions (kg/MT) | D43: AVERAGE of Unit_Cost ($) | F43: Soy Protein | G43: AgroSource Intl. | H43: BioFeedstock Ltd. | I43: EcoMaterials Co. | J43: GreenFibre BV | K43: NaturInput GmbH | L43: PalmEco Corp | M43: SustainSource Inc.
...

Sheet Sales Pivot
A1: SUM of Weighted_Revenue ($) | B1: Category_Interest
A2: Month | B2: Automotive Solutions | C2: Consumer & Home Care | D2: Industrial Lubricants | E2: Packaging Materials | F2: Specialty Polymers | G2: Grand Total
A3: 1 | F3: 56200000 | G3: 56200000
A4: 2 | B4: 197700000 | C4: 177400000 | D4: 215500000 | E4: 70200000 | F4: 199100000 | G4: 859900000
A5: 3 | B5: 68400000 | C5: 145000000 | D5: 68900000 | E5: 67300000 | F5: 111800000 | G5: 461400000
A6: 4 | B6: 78300000 | C6: 291400000 | D6: 168600000 | E6: 210400000 | F6: 216300000 | G6: 965000000
A7: 5 | B7: 188000000 | C7: 51900000 | D7: 156500000 | E7: 132800000 | F7: 66400000 | G7: 595600000
A8: 6 | C8: 116400000 | D8: 354300000 | E8: 135000000 | F8: 212900000 | G8: 818600000
A9: 7 | B9: 425700000 | C9: 44300000 | D9: 272100000 | F9: 54000000 | G9: 796100000
A10: 8 | B10: 171800000 | C10: 72100000 | D10: 15400000 | E10: 134400000 | F10: 196200000 | G10: 589900000
A11: 9 | B11: 176900000 | C11: 68900000 | D11: 232400000 | E11: 79100000 | F11: 154600000 | G11: 711900000
A12: 10 | B12: 64300000 | C12: 176900000 | D12: 357300000 | E12: 484700000 | F12: 195300000 | G12: 1278500000
A13: Grand Total | B13: 1371100000 | C13: 1144300000 | D13: 1841000000 | E13: 1313900000 | F13: 1462800000 | G13: 7133100000

Sheet Profit YTD2025
A1: Month | B1: Closed-Lost | C1: Closed-Won | D1: Negotiation | E1: Proposal Sent | F1: Prospecting | G1: Total | H1: Win Rate | J1: Month | K1: Automotive Solutions | L1: Consumer & Home Care | M1: Industrial Lubricants | N1: Packaging Materials | O1: Specialty Polymers | P1: Grand Total
A2: 1 | B2: 1 | C2: 1 | F2: 1 | G2: 3 | H2: =C2/G2 -> 0.33333333 | J2: 1 | O2: 56200000 | P2: 56200000
A3: 2 | B3: 15 | C3: 20 | D3: 15 | E3: 14 | F3: 19 | G3: 83 | H3: =C3/G3 -> 0.24096386 | J3: 2 | K3: 197700000 | L3: 177400000 | M3: 215500000 | N3: 70200000 | O3: 199100000 | P3: 859900000
A4: 3 | B4: 18 | C4: 15 | D4: 16 | E4: 24 | F4: 15 | G4: 88 | H4: =C4/G4 -> 0.17045455 | J4: 3 | K4: 68400000 | L4: 145000000 | M4: 68900000 | N4: 67300000 | O4: 111800000 | P4: 461400000
A5: 4 | B5: 17 | C5: 20 | D5: 9 | E5: 16 | F5: 10 | G5: 72 | H5: =C5/G5 -> 0.27777778 | J5: 4 | K5: 78300000 | L5: 291400000 | M5: 168600000 | N5: 210400000 | O5: 216300000 | P5: 965000000
A6: 5 | B6: 14 | C6: 16 | D6: 17 | E6: 20 | F6: 13 | G6: 80 | H6: =C6/G6 -> 0.2 | J6: 5 | K6: 188000000 | L6: 51900000 | M6: 156500000 | N6: 132800000 | O6: 66400000 | P6: 595600000
A7: 6 | B7: 19 | C7: 17 | D7: 12 | E7: 16 | F7: 12 | G7: 76 | H7: =C7/G7 -> 0.22368421 | J7: 6 | L7: 116400000 | M7: 354300000 | N7: 135000000 | O7: 212900000 | P7: 818600000
A8: 7 | B8: 14 | C8: 14 | D8: 19 | E8: 14 | F8: 5 | G8: 66 | H8: =C8/G8 -> 0.21212121 | J8: 7 | K8: 425700000 | L8: 44300000 | M8: 272100000 | O8: 54000000 | P8: 796100000
A9: 8 | B9: 15 | C9: 18 | D9: 19 | E9: 28 | F9: 17 | G9: 97 | H9: =C9/G9 -> 0.18556701 | J9: 8 | K9: 171800000 | L9: 72100000 | M9: 15400000 | N9: 134400000 | O9: 196200000 | P9: 589900000
A10: 9 | B10: 15 | C10: 16 | D10: 17 | E10: 9 | F10: 15 | G10: 72 | H10: =C10/G10 -> 0.22222222 | J10: 9 | K10: 176900000 | L10: 68900000 | M10: 232400000 | N10: 79100000 | O10: 154600000 | P10: 711900000
A11: 10 | B11: 14 | C11: 27 | D11: 13 | E11: 11 | F11: 17 | G11: 82 | H11: =C11/G11 -> 0.32926829 | J11: 10 | K11: 64300000 | L11: 176900000 | M11: 357300000 | N11: 484700000 | O11: 195300000 | P11: 1278500000
A12: 11 | B12: 16 | C12: 17 | D12: 13 | E12: 11 | F12: 21 | G12: 78 | H12: =C12/G12 -> 0.21794872 | J12: Grand Total | K12: 1371100000 | L12: 1144300000 | M12: 1841000000 | N12: 1313900000 | O12: 1462800000 | P12: 7133100000
A13: 12 | B13: 23 | C13: 15 | D13: 20 | E13: 18 | F13: 16 | G13: 92 | H13: =C13/G13 -> 0.16304348
A14: Grand Total | B14: 181 | C14: 196 | D14: 170 | E14: 181 | F14: 161 | G14: 889 | H14: =C14/G14 -> 0.22047244
A16: Category_Interest | B16: Closed-Lost | C16: Closed-Won | D16: Negotiation | E16: Proposal Sent | F16: Prospecting | G16: Total | H16: Win Rate | J16: YTD 2025 | K16: Automotive Solutions | L16: Consumer & Home Care | M16: Industrial Lubricants | N16: Packaging Materials | O16: Specialty Polymers | P16: Total MC
A17: Automotive Solutions | B17: 27 | C17: 41 | D17: 46 | E17: 40 | F17: 39 | G17: 193 | H17: =C17/G17 -> 0.21243523 | J17: 1 | K17: =sumifs(Manufacturing!K:K,Manufacturing!O:O,$K$16,Manufacturing!M:M,2025,Manufacturing!N:N,J17) -> 1.6236935e+08 | L17: =sumifs(Manufacturing!K:K,Manufacturing!O:O,$L$16,Manufacturing!M:M,2025,Manufacturing!N:N,J17) -> 120856389 | M17: =sumifs(Manufacturing!K:K,Manufacturing!O:O,$M$16,Manufacturing!M:M,2025,Manufacturing!N:N,J17) -> 1.2119805e+08 | N17: =sumifs(Manufacturing!K:K,Manufacturing!O:O,$N$16,Manufacturing!M:M,2025,Manufacturing!N:N,J17) -> 1.1305363e+08 | O17: =sumifs(Manufacturing!K:K,Manufacturing!O:O,$O$16,Manufacturing!M:M,2025,Manufacturing!N:N,J17) -> 1.0417001e+08 | P17: =SUM(K17:O17) -> 6.2164743e+08
A18: Consumer & Home Care | B18: 39 | C18: 30 | D18: 27 | E18: 41 | F18: 40 | G18: 177 | H18: =C18/G18 -> 0.16949153 | J18: 2 | K18: =sumifs(Manufacturing!K:K,Manufacturing!O:O,$K$16,Manufacturing!M:M,2025,Manufacturing!N:N,J18) -> 71846936 | L18: =sumifs(Manufacturing!K:K,Manufacturing!O:O,$L$16,Manufacturing!M:M,2025,Manufacturing!N:N,J18) -> 1.0713998e+08 | M18: =sumifs(Manufacturing!K:K,Manufacturing!O:O,$M$16,Manufacturing!M:M,2025,Manufacturing!N:N,J18) -> 86902725 | N18: =sumifs(Manufacturing!K:K,Manufacturing!O:O,$N$16,Manufacturing!M:M,2025,Manufacturing!N:N,J18) -> 84902363 | O18: =sumifs(Manufacturing!K:K,Manufacturing!O:O,$O$16,Manufacturing!M:M,2025,Manufacturing!N:N,J18) -> 1.1169817e+08 | P18: =SUM(K18:O18) -> 4.6249017e+08
A19: Industrial Lubricants | B19: 42 | C19: 49 | D19: 27 | E19: 35 | F19: 28 | G19: 181 | H19: =C19/G19 -> 0.27071823 | J19: 3 | K19: =sumifs(Manufacturing!K:K,Manufacturing!O:O,$K$16,Manufacturing!M:M,2025,Manufacturing!N:N,J19) -> 81725199 | L19: =sumifs(Manufacturing!K:K,Manufacturing!O:O,$L$16,Manufacturing!M:M,2025,Manufacturing!N:N,J19) -> 87090562 | M19: =sumifs(Manufacturing!K:K,Manufacturing!O:O,$M$16,Manufacturing!M:M,2025,Manufacturing!N:N,J19) -> 1.0049137e+08 | N19: =sumifs(Manufacturing!K:K,Manufacturing!O:O,$N$16,Manufacturing!M:M,2025,Manufacturing!N:N,J19) -> 1.1179408e+08 | O19: =sumifs(Manufacturing!K:K,Manufacturing!O:O,$O$16,Manufacturing!M:M,2025,Manufacturing!N:N,J19) -> 1.0475758e+08 | P19: =SUM(K19:O19) -> 4.8585879e+08
A20: Packaging Materials | B20: 35 | C20: 33 | D20: 34 | E20: 23 | F20: 33 | G20: 158 | H20: =C20/G20 -> 0.20886076 | J20: 4 | K20: =sumifs(Manufacturing!K:K,Manufacturing!O:O,$K$16,Manufacturing!M:M,2025,Manufacturing!N:N,J20) -> 99426749 | L20: =sumifs(Manufacturing!K:K,Manufacturing!O:O,$L$16,Manufacturing!M:M,2025,Manufacturing!N:N,J20) -> 1.1021303e+08 | M20: =sumifs(Manufacturing!K:K,Manufacturing!O:O,$M$16,Manufacturing!M:M,2025,Manufacturing!N:N,J20) -> 1.0455878e+08 | N20: =sumifs(Manufacturing!K:K,Manufacturing!O:O,$N$16,Manufacturing!M:M,2025,Manufacturing!N:N,J20) -> 78856736 | O20: =sumifs(Manufacturing!K:K,Manufacturing!O:O,$O$16,Manufacturing!M:M,2025,Manufacturing!N:N,J20) -> 1.0316204e+08 | P20: =SUM(K20:O20) -> 4.9621733e+08
A21: Specialty Polymers | B21: 38 | C21: 43 | D21: 36 | E21: 42 | F21: 21 | G21: 180 | H21: =C21/G21 -> 0.23888889 | J21: 5 | K21: =sumifs(Manufacturing!K:K,Manufacturing!O:O,$K$16,Manufacturing!M:M,2025,Manufacturing!N:N,J21) -> 94140937 | L21: =sumifs(Manufacturing!K:K,Manufacturing!O:O,$L$16,Manufacturing!M:M,2025,Manufacturing!N:N,J21) -> 92844553 | M21: =sumifs(Manufacturing!K:K,Manufacturing!O:O,$M$16,Manufacturing!M:M,2025,Manufacturing!N:N,J21) -> 105884162 | N21: =sumifs(Manufacturing!K:K,Manufacturing!O:O,$N$16,Manufacturing!M:M,2025,Manufacturing!N:N,J21) -> 1.3939305e+08 | O21: =sumifs(Manufacturing!K:K,Manufacturing!O:O,$O$16,Manufacturing!M:M,2025,Manufacturing!N:N,J21) -> 134471021 | P21: =SUM(K21:O21) -> 566733728
A22: Grand Total | B22: 181 | C22: 196 | D22: 170 | E22: 181 | F22: 161 | G22: 889 | H22: =C22/G22 -> 0.22047244 | J22: 6 | K22: =sumifs(Manufacturing!K:K,Manufacturing!O:O,$K$16,Manufacturing!M:M,2025,Manufacturing!N:N,J22) -> 92648442 | L22: =sumifs(Manufacturing!K:K,Manufacturing!O:O,$L$16,Manufacturing!M:M,2025,Manufacturing!N:N,J22) -> 1.671091e+08 | M22: =sumifs(Manufacturing!K:K,Manufacturing!O:O,$M$16,Manufacturing!M:M,2025,Manufacturing!N:N,J22) -> 78554991 | N22: =sumifs(Manufacturing!K:K,Manufacturing!O:O,$N$16,Manufacturing!M:M,2025,Manufacturing!N:N,J22) -> 89449457 | O22: =sumifs(Manufacturing!K:K,Manufacturing!O:O,$O$16,Manufacturing!M:M,2025,Manufacturing!N:N,J22) -> 1.0601886e+08 | P22: =SUM(K22:O22) -> 5.3378086e+08
J23: 7 | K23: =sumifs(Manufacturing!K:K,Manufacturing!O:O,$K$16,Manufacturing!M:M,2025,Manufacturing!N:N,J23) -> 1.0304386e+08 | L23: =sumifs(Manufacturing!K:K,Manufacturing!O:O,$L$16,Manufacturing!M:M,2025,Manufacturing!N:N,J23) -> 94168300 | M23: =sumifs(Manufacturing!K:K,Manufacturing!O:O,$M$16,Manufacturing!M:M,2025,Manufacturing!N:N,J23) -> 1.5730977e+08 | N23: =sumifs(Manufacturing!K:K,Manufacturing!O:O,$N$16,Manufacturing!M:M,2025,Manufacturing!N:N,J23) -> 1.3303016e+08 | O23: =sumifs(Manufacturing!K:K,Manufacturing!O:O,$O$16,Manufacturing!M:M,2025,Manufacturing!N:N,J23) -> 94537843 | P23: =SUM(K23:O23) -> 5.8208993e+08
J24: 8 | K24: =sumifs(Manufacturing!K:K,Manufacturing!O:O,$K$16,Manufacturing!M:M,2025,Manufacturing!N:N,J24) -> 95612380 | L24: =sumifs(Manufacturing!K:K,Manufacturing!O:O,$L$16,Manufacturing!M:M,2025,Manufacturing!N:N,J24) -> 1.1074918e+08 | M24: =sumifs(Manufacturing!K:K,Manufacturing!O:O,$M$16,Manufacturing!M:M,2025,Manufacturing!N:N,J24) -> 81448161 | N24: =sumifs(Manufacturing!K:K,Manufacturing!O:O,$N$16,Manufacturing!M:M,2025,Manufacturing!N:N,J24) -> 1.2544424e+08 | O24: =sumifs(Manufacturing!K:K,Manufacturing!O:O,$O$16,Manufacturing!M:M,2025,Manufacturing!N:N,J24) -> 1.5523156e+08 | P24: =SUM(K24:O24) -> 5.6848553e+08
J25: 9 | K25: =sumifs(Manufacturing!K:K,Manufacturing!O:O,$K$16,Manufacturing!M:M,2025,Manufacturing!N:N,J25) -> 1.1198364e+08 | L25: =sumifs(Manufacturing!K:K,Manufacturing!O:O,$L$16,Manufacturing!M:M,2025,Manufacturing!N:N,J25) -> 1.1232708e+08 | M25: =sumifs(Manufacturing!K:K,Manufacturing!O:O,$M$16,Manufacturing!M:M,2025,Manufacturing!N:N,J25) -> 1.1709291e+08 | N25: =sumifs(Manufacturing!K:K,Manufacturing!O:O,$N$16,Manufacturing!M:M,2025,Manufacturing!N:N,J25) -> 98911461 | O25: =sumifs(Manufacturing!K:K,Manufacturing!O:O,$O$16,Manufacturing!M:M,2025,Manufacturing!N:N,J25) -> 90935814 | P25: =SUM(K25:O25) -> 5.312509e+08
J26: 10 | K26: =sumifs(Manufacturing!K:K,Manufacturing!O:O,$K$16,Manufacturing!M:M,2025,Manufacturing!N:N,J26) -> 1.0327739e+08 | L26: =sumifs(Manufacturing!K:K,Manufacturing!O:O,$L$16,Manufacturing!M:M,2025,Manufacturing!N:N,J26) -> 99978615 | M26: =sumifs(Manufacturing!K:K,Manufacturing!O:O,$M$16,Manufacturing!M:M,2025,Manufacturing!N:N,J26) -> 1.2306089e+08 | N26: =sumifs(Manufacturing!K:K,Manufacturing!O:O,$N$16,Manufacturing!M:M,2025,Manufacturing!N:N,J26) -> 1.0832454e+08 | O26: =sumifs(Manufacturing!K:K,Manufacturing!O:O,$O$16,Manufacturing!M:M,2025,Manufacturing!N:N,J26) -> 1.2009814e+08 | P26: =SUM(K26:O26) -> 5.5473958e+08
J27: Grand Total | K27: =sum(K18:K26) -> 8.5370553e+08 | L27: =sum(L18:L26) -> 9.8162039e+08 | M27: =sum(M18:M26) -> 9.5530377e+08 | N27: =sum(N18:N26) -> 9.7010609e+08 | O27: =sum(O18:O26) -> 1020911047 | P27: =SUM(K27:O27) -> 4781646824
J29: YTD 2025 | K29: Total Revenue | L29: Total Cost | M29: Profit | N29: Profit Margin | O29: CO2 Emissions
J30: 1 | K30: =xlookup(J30,J2:J10,P2:P10) -> 56200000 | L30: {=xlookup(J30,J17:J26,P17:P26)+sumifs('Supply Chain'!M:M,'Supply Chain'!J:J,2025,'Supply Chain'!I:I,J30)} -> 689618827 | M30: =K30-L30 -> -633418827 | N30: =M30/K30 -> -11.270798 | O30: =sumifs('Supply Chain'!N:N,'Supply Chain'!J:J,2025,'Supply Chain'!I:I,J30) -> 45717989
J31: 2 | K31: =xlookup(J31,J3:J11,P3:P11) -> 859900000 | L31: {=xlookup(J31,J18:J27,P18:P27)+sumifs('Supply Chain'!M:M,'Supply Chain'!J:J,2025,'Supply Chain'!I:I,J31)} -> 5.1976973e+08 | M31: =K31-L31 -> 3.4013027e+08 | N31: =M31/K31 -> 0.3955463 | O31: =sumifs('Supply Chain'!N:N,'Supply Chain'!J:J,2025,'Supply Chain'!I:I,J31) -> 38727339
J32: 3 | K32: =xlookup(J32,J4:J12,P4:P12) -> 461400000 | L32: {=xlookup(J32,J19:J28,P19:P28)+sumifs('Supply Chain'!M:M,'Supply Chain'!J:J,2025,'Supply Chain'!I:I,J32)} -> 5.4563144e+08 | M32: =K32-L32 -> -84231444 | N32: =M32/K32 -> -0.18255623 | O32: =sumifs('Supply Chain'!N:N,'Supply Chain'!J:J,2025,'Supply Chain'!I:I,J32) -> 39789437
J33: 4 | K33: =xlookup(J33,J5:J13,P5:P13) -> 965000000 | L33: {=xlookup(J33,J20:J29,P20:P29)+sumifs('Supply Chain'!M:M,'Supply Chain'!J:J,2025,'Supply Chain'!I:I,J33)} -> 5.5500012e+08 | M33: =K33-L33 -> 4.0999988e+08 | N33: =M33/K33 -> 0.42487034 | O33: =sumifs('Supply Chain'!N:N,'Supply Chain'!J:J,2025,'Supply Chain'!I:I,J33) -> 39592382
J34: 5 | K34: =xlookup(J34,J6:J14,P6:P14) -> 595600000 | L34: {=xlookup(J34,J21:J30,P21:P30)+sumifs('Supply Chain'!M:M,'Supply Chain'!J:J,2025,'Supply Chain'!I:I,J34)} -> 6.2650403e+08 | M34: =K34-L34 -> -30904030 | N34: =M34/K34 -> -0.051887223 | O34: =sumifs('Supply Chain'!N:N,'Supply Chain'!J:J,2025,'Supply Chain'!I:I,J34) -> 36912038
J35: 6 | K35: =xlookup(J35,J7:J15,P7:P15) -> 818600000 | L35: {=xlookup(J35,J22:J31,P22:P31)+sumifs('Supply Chain'!M:M,'Supply Chain'!J:J,2025,'Supply Chain'!I:I,J35)} -> 5.9455562e+08 | M35: =K35-L35 -> 2.2404438e+08 | N35: =M35/K35 -> 0.27369214 | O35: =sumifs('Supply Chain'!N:N,'Supply Chain'!J:J,2025,'Supply Chain'!I:I,J35) -> 37651460
J36: 7 | K36: =xlookup(J36,J8:J16,P8:P16) -> 796100000 | L36: {=xlookup(J36,J23:J32,P23:P32)+sumifs('Supply Chain'!M:M,'Supply Chain'!J:J,2025,'Supply Chain'!I:I,J36)} -> 6.4545535e+08 | M36: =K36-L36 -> 1.5064465e+08 | N36: =M36/K36 -> 0.1892283 | O36: =sumifs('Supply Chain'!N:N,'Supply Chain'!J:J,2025,'Supply Chain'!I:I,J36) -> 42583105
J37: 8 | K37: =xlookup(J37,J9:J17,P9:P17) -> 589900000 | L37: {=xlookup(J37,J24:J33,P24:P33)+sumifs('Supply Chain'!M:M,'Supply Chain'!J:J,2025,'Supply Chain'!I:I,J37)} -> 6.2355377e+08 | M37: =K37-L37 -> -33653772 | N37: =M37/K37 -> -0.057049961 | O37: =sumifs('Supply Chain'!N:N,'Supply Chain'!J:J,2025,'Supply Chain'!I:I,J37) -> 38699109
J38: 9 | K38: =xlookup(J38,J10:J18,P10:P18) -> 711900000 | L38: {=xlookup(J38,J25:J34,P25:P34)+sumifs('Supply Chain'!M:M,'Supply Chain'!J:J,2025,'Supply Chain'!I:I,J38)} -> 5.887631e+08 | M38: =K38-L38 -> 1.231369e+08 | N38: =M38/K38 -> 0.17296938 | O38: =sumifs('Supply Chain'!N:N,'Supply Chain'!J:J,2025,'Supply Chain'!I:I,J38) -> 39313772
J39: 10 | K39: =xlookup(J39,J11:J19,P11:P19) -> 1278500000 | L39: {=xlookup(J39,J26:J35,P26:P35)+sumifs('Supply Chain'!M:M,'Supply Chain'!J:J,2025,'Supply Chain'!I:I,J39)} -> 6.1921568e+08 | M39: =K39-L39 -> 6.5928432e+08 | N39: =M39/K39 -> 0.51567018 | O39: =sumifs('Supply Chain'!N:N,'Supply Chain'!J:J,2025,'Supply Chain'!I:I,J39) -> 42944576
J40: Grand Total | K40: =xlookup(J40,J12:J20,P12:P20) -> 7133100000 | L40: {=xlookup(J40,J27:J36,P27:P36)+sumifs('Supply Chain'!M:M,'Supply Chain'!J:J,2025,'Supply Chain'!I:I,J40)} -> 4781646824 | M40: =K40-L40 -> 2351453176 | N40: =M40/K40 -> 0.32965375 | O40: =sumifs('Supply Chain'!N:N,'Supply Chain'!J:J,2025,'Supply Chain'!I:I,J40) -> 0

Sheet SSI
A1: RawMaterial_Name | B1: Supplier_Name | C1: AVERAGE of Unit_Cost ($) | D1: AVERAGE of CO2_Emissions (kg/MT) | E1: Delivery Rate | F1: Cost Score | G1: CO2 Score | H1: Deliver Score | I1: SSI (100) | J1: Rank
A2: Algae Oil | B2: AgroSource Intl. | C2: 460.6764 | D2: 320.032 | E2: =countifs('Supply Chain'!D:D,A2,'Supply Chain'!B:B,B2,'Supply Chain'!J:J,2025,'Supply Chain'!K:K,"Y")/countifs('Supply Chain'!D:D,A2,'Supply Chain'!B:B,B2,'Supply Chain'!J:J,2025) -> 0.46 | F2: =100*(max($C$2:$C$8)-C2)/(max($C$2:$C$8)-min($C$2:$C$8)) -> 11.465946 | G2: =100*(max($D$2:$D$8)-D2)/(max($D$2:$D$8)-min($D$2:$D$8)) -> 34.185532 | H2: =100*(max($E$2:$E$8)-E2)/(max($E$2:$E$8)-min($E$2:$E$8)) -> 39.710396 | I2: =0.4*F2+0.4*G2+0.2*H2 -> 26.20267 | J2: =IFERROR(__xludf.DUMMYFUNCTION("RANK.EQ(I2,filter(I:I,A:A=A2))"),7.0) -> 7
A3: Algae Oil | B3: BioFeedstock Ltd. | C3: 440.32173 | D3: 336.23077 | E3: =countifs('Supply Chain'!D:D,A3,'Supply Chain'!B:B,B3,'Supply Chain'!J:J,2025,'Supply Chain'!K:K,"Y")/countifs('Supply Chain'!D:D,A3,'Supply Chain'!B:B,B3,'Supply Chain'!J:J,2025) -> 0.51923077 | F3: =100*(max($C$2:$C$8)-C3)/(max($C$2:$C$8)-min($C$2:$C$8)) -> 97.331759 | G3: =100*(max($D$2:$D$8)-D3)/(max($D$2:$D$8)-min($D$2:$D$8)) -> 0 | H3: =100*(max($E$2:$E$8)-E3)/(max($E$2:$E$8)-min($E$2:$E$8)) -> 8.85615 | I3: =0.4*F3+0.4*G3+0.2*H3 -> 40.703934 | J3: =IFERROR(__xludf.DUMMYFUNCTION("RANK.EQ(I3,filter(I:I,A:A=A3))"),5.0) -> 5
A4: Algae Oil | B4: EcoMaterials Co. | C4: 452.54902 | D4: 304.38852 | E4: =countifs('Supply Chain'!D:D,A4,'Supply Chain'!B:B,B4,'Supply Chain'!J:J,2025,'Supply Chain'!K:K,"Y")/countifs('Supply Chain'!D:D,A4,'Supply Chain'!B:B,B4,'Supply Chain'!J:J,2025) -> 0.49180328 | F4: =100*(max($C$2:$C$8)-C4)/(max($C$2:$C$8)-min($C$2:$C$8)) -> 45.75117 | G4: =100*(max($D$2:$D$8)-D4)/(max($D$2:$D$8)-min($D$2:$D$8)) -> 67.199185 | H4: =100*(max($E$2:$E$8)-E4)/(max($E$2:$E$8)-min($E$2:$E$8)) -> 23.143564 | I4: =0.4*F4+0.4*G4+0.2*H4 -> 49.808855 | J4: =IFERROR(__xludf.DUMMYFUNCTION("RANK.EQ(I4,filter(I:I,A:A=A4))"),4.0) -> 4
A5: Algae Oil | B5: GreenFibre BV | C5: 445.46132 | D5: 315.14265 | E5: =countifs('Supply Chain'!D:D,A5,'Supply Chain'!B:B,B5,'Supply Chain'!J:J,2025,'Supply Chain'!K:K,"Y")/countifs('Supply Chain'!D:D,A5,'Supply Chain'!B:B,B5,'Supply Chain'!J:J,2025) -> 0.38235294 | F5: =100*(max($C$2:$C$8)-C5)/(max($C$2:$C$8)-min($C$2:$C$8)) -> 75.650478 | G5: =100*(max($D$2:$D$8)-D5)/(max($D$2:$D$8)-min($D$2:$D$8)) -> 44.503917 | H5: =100*(max($E$2:$E$8)-E5)/(max($E$2:$E$8)-min($E$2:$E$8)) -> 80.157979 | I5: =0.4*F5+0.4*G5+0.2*H5 -> 64.093354 | J5: =IFERROR(__xludf.DUMMYFUNCTION("RANK.EQ(I5,filter(I:I,A:A=A5))"),1.0) -> 1
A6: Algae Oil | B6: NaturInput GmbH | C6: 439.68922 | D6: 328.12969 | E6: =countifs('Supply Chain'!D:D,A6,'Supply Chain'!B:B,B6,'Supply Chain'!J:J,2025,'Supply Chain'!K:K,"Y")/countifs('Supply Chain'!D:D,A6,'Supply Chain'!B:B,B6,'Supply Chain'!J:J,2025) -> 0.40625 | F6: =100*(max($C$2:$C$8)-C6)/(max($C$2:$C$8)-min($C$2:$C$8)) -> 100 | G6: =100*(max($D$2:$D$8)-D6)/(max($D$2:$D$8)-min($D$2:$D$8)) -> 17.096348 | H6: =100*(max($E$2:$E$8)-E6)/(max($E$2:$E$8)-min($E$2:$E$8)) -> 67.709623 | I6: =0.4*F6+0.4*G6+0.2*H6 -> 60.380464 | J6: =IFERROR(__xludf.DUMMYFUNCTION("RANK.EQ(I6,filter(I:I,A:A=A6))"),2.0) -> 2
A7: Algae Oil | B7: PalmEco Corp | C7: 463.39443 | D7: 288.8459 | E7: =countifs('Supply Chain'!D:D,A7,'Supply Chain'!B:B,B7,'Supply Chain'!J:J,2025,'Supply Chain'!K:K,"Y")/countifs('Supply Chain'!D:D,A7,'Supply Chain'!B:B,B7,'Supply Chain'!J:J,2025) -> 0.3442623 | F7: =100*(max($C$2:$C$8)-C7)/(max($C$2:$C$8)-min($C$2:$C$8)) -> 0 | G7: =100*(max($D$2:$D$8)-D7)/(max($D$2:$D$8)-min($D$2:$D$8)) -> 100 | H7: =100*(max($E$2:$E$8)-E7)/(max($E$2:$E$8)-min($E$2:$E$8)) -> 100 | I7: =0.4*F7+0.4*G7+0.2*H7 -> 60 | J7: =IFERROR(__xludf.DUMMYFUNCTION("RANK.EQ(I7,filter(I:I,A:A=A7))"),3.0) -> 3
A8: Algae Oil | B8: SustainSource Inc. | C8: 454.82623 | D8: 309.27681 | E8: =countifs('Supply Chain'!D:D,A8,'Supply Chain'!B:B,B8,'Supply Chain'!J:J,2025,'Supply Chain'!K:K,"Y")/countifs('Supply Chain'!D:D,A8,'Supply Chain'!B:B,B8,'Supply Chain'!J:J,2025) -> 0.53623188 | F8: =100*(max($C$2:$C$8)-C8)/(max($C$2:$C$8)-min($C$2:$C$8)) -> 36.144777 | G8: =100*(max($D$2:$D$8)-D8)/(max($D$2:$D$8)-min($D$2:$D$8)) -> 56.883049 | H8: =100*(max($E$2:$E$8)-E8)/(max($E$2:$E$8)-min($E$2:$E$8)) -> 0 | I8: =0.4*F8+0.4*G8+0.2*H8 -> 37.211131 | J8: =IFERROR(__xludf.DUMMYFUNCTION("RANK.EQ(I8,filter(I:I,A:A=A8))"),6.0) -> 6
A9: Cassava Starch | B9: AgroSource Intl. | C9: 448.1788 | D9: 300.304 | E9: =countifs('Supply Chain'!D:D,A9,'Supply Chain'!B:B,B9,'Supply Chain'!J:J,2025,'Supply Chain'!K:K,"Y")/countifs('Supply Chain'!D:D,A9,'Supply Chain'!B:B,B9,'Supply Chain'!J:J,2025) -> 0.46666667 | F9: =100*(max($C$9:$C$15)-C9)/(max($C$9:$C$15)-min($C$9:$C$15)) -> 45.233345 | G9: =100*(max($D$9:$D$15)-D9)/(max($D$9:$D$15)-min($D$9:$D$15)) -> 72.269697 | H9: =100*(max($E$9:$E$15)-E9)/(max($E$9:$E$15)-min($E$9:$E$15)) -> 63.485035 | I9: =0.4*F9+0.4*G9+0.2*H9 -> 59.698224 | J9: =IFERROR(__xludf.DUMMYFUNCTION("RANK.EQ(I9,filter(I:I,A:A=A9))"),3.0) -> 3
A10: Cassava Starch | B10: BioFeedstock Ltd. | C10: 447.59151 | D10: 319.62264 | E10: =countifs('Supply Chain'!D:D,A10,'Supply Chain'!B:B,B10,'Supply Chain'!J:J,2025,'Supply Chain'!K:K,"Y")/countifs('Supply Chain'!D:D,A10,'Supply Chain'!B:B,B10,'Supply Chain'!J:J,2025) -> 0.45283019 | F10: =100*(max($C$9:$C$15)-C10)/(max($C$9:$C$15)-min($C$9:$C$15)) -> 46.629037 | G10: =100*(max($D$9:$D$15)-D10)/(max($D$9:$D$15)-min($D$9:$D$15)) -> 30.788362 | H10: =100*(max($E$9:$E$15)-E10)/(max($E$9:$E$15)-min($E$9:$E$15)) -> 68.572025 | I10: =0.4*F10+0.4*G10+0.2*H10 -> 44.681365 | J10: =IFERROR(__xludf.DUMMYFUNCTION("RANK.EQ(I10,filter(I:I,A:A=A10))"),6.0) -> 6
A11: Cassava Starch | B11: EcoMaterials Co. | C11: 435.64735 | D11: 289.10408 | E11: =countifs('Supply Chain'!D:D,A11,'Supply Chain'!B:B,B11,'Supply Chain'!J:J,2025,'Supply Chain'!K:K,"Y")/countifs('Supply Chain'!D:D,A11,'Supply Chain'!B:B,B11,'Supply Chain'!J:J,2025) -> 0.36734694 | F11: =100*(max($C$9:$C$15)-C11)/(max($C$9:$C$15)-min($C$9:$C$15)) -> 75.014247 | G11: =100*(max($D$9:$D$15)-D11)/(max($D$9:$D$15)-min($D$9:$D$15)) -> 96.318363 | H11: =100*(max($E$9:$E$15)-E11)/(max($E$9:$E$15)-min($E$9:$E$15)) -> 100 | I11: =0.4*F11+0.4*G11+0.2*H11 -> 88.533044 | J11: =IFERROR(__xludf.DUMMYFUNCTION("RANK.EQ(I11,filter(I:I,A:A=A11))"),1.0) -> 1
A12: Cassava Starch | B12: GreenFibre BV | C12: 447.1883 | D12: 311.89057 | E12: =countifs('Supply Chain'!D:D,A12,'Supply Chain'!B:B,B12,'Supply Chain'!J:J,2025,'Supply Chain'!K:K,"Y")/countifs('Supply Chain'!D:D,A12,'Supply Chain'!B:B,B12,'Supply Chain'!J:J,2025) -> 0.45283019 | F12: =100*(max($C$9:$C$15)-C12)/(max($C$9:$C$15)-min($C$9:$C$15)) -> 47.587256 | G12: =100*(max($D$9:$D$15)-D12)/(max($D$9:$D$15)-min($D$9:$D$15)) -> 47.390814 | H12: =100*(max($E$9:$E$15)-E12)/(max($E$9:$E$15)-min($E$9:$E$15)) -> 68.572025 | I12: =0.4*F12+0.4*G12+0.2*H12 -> 51.705633 | J12: =IFERROR(__xludf.DUMMYFUNCTION("RANK.EQ(I12,filter(I:I,A:A=A12))"),4.0) -> 4
A13: Cassava Starch | B13: NaturInput GmbH | C13: 455.7693 | D13: 287.38947 | E13: =countifs('Supply Chain'!D:D,A13,'Supply Chain'!B:B,B13,'Supply Chain'!J:J,2025,'Supply Chain'!K:K,"Y")/countifs('Supply Chain'!D:D,A13,'Supply Chain'!B:B,B13,'Supply Chain'!J:J,2025) -> 0.50877193 | F13: =100*(max($C$9:$C$15)-C13)/(max($C$9:$C$15)-min($C$9:$C$15)) -> 27.194584 | G13: =100*(max($D$9:$D$15)-D13)/(max($D$9:$D$15)-min($D$9:$D$15)) -> 100 | H13: =100*(max($E$9:$E$15)-E13)/(max($E$9:$E$15)-min($E$9:$E$15)) -> 48.005006 | I13: =0.4*F13+0.4*G13+0.2*H13 -> 60.478835 | J13: =IFERROR(__xludf.DUMMYFUNCTION("RANK.EQ(I13,filter(I:I,A:A=A13))"),2.0) -> 2
A14: Cassava Starch | B14: PalmEco Corp | C14: 425.13364 | D14: 333.96136 | E14: =countifs('Supply Chain'!D:D,A14,'Supply Chain'!B:B,B14,'Supply Chain'!J:J,2025,'Supply Chain'!K:K,"Y")/countifs('Supply Chain'!D:D,A14,'Supply Chain'!B:B,B14,'Supply Chain'!J:J,2025) -> 0.52272727 | F14: =100*(max($C$9:$C$15)-C14)/(max($C$9:$C$15)-min($C$9:$C$15)) -> 100 | G14: =100*(max($D$9:$D$15)-D14)/(max($D$9:$D$15)-min($D$9:$D$15)) -> 0 | H14: =100*(max($E$9:$E$15)-E14)/(max($E$9:$E$15)-min($E$9:$E$15)) -> 42.874315 | I14: =0.4*F14+0.4*G14+0.2*H14 -> 48.574863 | J14: =IFERROR(__xludf.DUMMYFUNCTION("RANK.EQ(I14,filter(I:I,A:A=A14))"),5.0) -> 5
A15: Cassava Starch | B15: SustainSource Inc. | C15: 467.21246 | D15: 298.8541 | E15: =countifs('Supply Chain'!D:D,A15,'Supply Chain'!B:B,B15,'Supply Chain'!J:J,2025,'Supply Chain'!K:K,"Y")/countifs('Supply Chain'!D:D,A15,'Supply Chain'!B:B,B15,'Supply Chain'!J:J,2025) -> 0.63934426 | F15: =100*(max($C$9:$C$15)-C15)/(max($C$9:$C$15)-min($C$9:$C$15)) -> 0 | G15: =100*(max($D$9:$D$15)-D15)/(max($D$9:$D$15)-min($D$9:$D$15)) -> 75.382952 | H15: =100*(max($E$9:$E$15)-E15)/(max($E$9:$E$15)-min($E$9:$E$15)) -> 0 | I15: =0.4*F15+0.4*G15+0.2*H15 -> 30.153181 | J15: =IFERROR(__xludf.DUMMYFUNCTION("RANK.EQ(I15,filter(I:I,A:A=A15))"),7.0) -> 7
A16: Corn Starch | B16: AgroSource Intl. | C16: 438.16385 | D16: 332.14615 | E16: =countifs('Supply Chain'!D:D,A16,'Supply Chain'!B:B,B16,'Supply Chain'!J:J,2025,'Supply Chain'!K:K,"Y")/countifs('Supply Chain'!D:D,A16,'Supply Chain'!B:B,B16,'Supply Chain'!J:J,2025) -> 0.46153846 | F16: =100*(max($C$16:$C$22)-C16)/(max($C$16:$C$22)-min($C$16:$C$22)) -> 87.765648 | G16: =100*(max($D$16:$D$22)-D16)/(max($D$16:$D$22)-min($D$16:$D$22)) -> 0 | H16: =100*(max($E$16:$E$22)-E16)/(max($E$16:$E$22)-min($E$16:$E$22)) -> 60.426035 | I16: =0.4*F16+0.4*G16+0.2*H16 -> 47.191466 | J16: =IFERROR(__xludf.DUMMYFUNCTION("RANK.EQ(I16,filter(I:I,A:A=A16))"),6.0) -> 6
A17: Corn Starch | B17: BioFeedstock Ltd. | C17: 440.74942 | D17: 328.74783 | E17: =countifs('Supply Chain'!D:D,A17,'Supply Chain'!B:B,B17,'Supply Chain'!J:J,2025,'Supply Chain'!K:K,"Y")/countifs('Supply Chain'!D:D,A17,'Supply Chain'!B:B,B17,'Supply Chain'!J:J,2025) -> 0.37681159 | F17: =100*(max($C$16:$C$22)-C17)/(max($C$16:$C$22)-min($C$16:$C$22)) -> 80.542014 | G17: =100*(max($D$16:$D$22)-D17)/(max($D$16:$D$22)-min($D$16:$D$22)) -> 5.7207201 | H17: =100*(max($E$16:$E$22)-E17)/(max($E$16:$E$22)-min($E$16:$E$22)) -> 100 | I17: =0.4*F17+0.4*G17+0.2*H17 -> 54.505094 | J17: =IFERROR(__xludf.DUMMYFUNCTION("RANK.EQ(I17,filter(I:I,A:A=A17))"),3.0) -> 3
A18: Corn Starch | B18: EcoMaterials Co. | C18: 433.89846 | D18: 272.74231 | E18: =countifs('Supply Chain'!D:D,A18,'Supply Chain'!B:B,B18,'Supply Chain'!J:J,2025,'Supply Chain'!K:K,"Y")/countifs('Supply Chain'!D:D,A18,'Supply Chain'!B:B,B18,'Supply Chain'!J:J,2025) -> 0.48076923 | F18: =100*(max($C$16:$C$22)-C18)/(max($C$16:$C$22)-min($C$16:$C$22)) -> 99.682374 | G18: =100*(max($D$16:$D$22)-D18)/(max($D$16:$D$22)-min($D$16:$D$22)) -> 100 | H18: =100*(max($E$16:$E$22)-E18)/(max($E$16:$E$22)-min($E$16:$E$22)) -> 51.443787 | I18: =0.4*F18+0.4*G18+0.2*H18 -> 90.161707 | J18: =IFERROR(__xludf.DUMMYFUNCTION("RANK.EQ(I18,filter(I:I,A:A=A18))"),1.0) -> 1
A19: Corn Starch | B19: GreenFibre BV | C19: 457.05662 | D19: 292.39385 | E19: =countifs('Supply Chain'!D:D,A19,'Supply Chain'!B:B,B19,'Supply Chain'!J:J,2025,'Supply Chain'!K:K,"Y")/countifs('Supply Chain'!D:D,A19,'Supply Chain'!B:B,B19,'Supply Chain'!J:J,2025) -> 0.49230769 | F19: =100*(max($C$16:$C$22)-C19)/(max($C$16:$C$22)-min($C$16:$C$22)) -> 34.982612 | G19: =100*(max($D$16:$D$22)-D19)/(max($D$16:$D$22)-min($D$16:$D$22)) -> 66.918744 | H19: =100*(max($E$16:$E$22)-E19)/(max($E$16:$E$22)-min($E$16:$E$22)) -> 46.054438 | I19: =0.4*F19+0.4*G19+0.2*H19 -> 49.97143 | J19: =IFERROR(__xludf.DUMMYFUNCTION("RANK.EQ(I19,filter(I:I,A:A=A19))"),5.0) -> 5
A20: Corn Starch | B20: NaturInput GmbH | C20: 442.96548 | D20: 291.62419 | E20: =countifs('Supply Chain'!D:D,A20,'Supply Chain'!B:B,B20,'Supply Chain'!J:J,2025,'Supply Chain'!K:K,"Y")/countifs('Supply Chain'!D:D,A20,'Supply Chain'!B:B,B20,'Supply Chain'!J:J,2025) -> 0.48387097 | F20: =100*(max($C$16:$C$22)-C20)/(max($C$16:$C$22)-min($C$16:$C$22)) -> 74.350727 | G20: =100*(max($D$16:$D$22)-D20)/(max($D$16:$D$22)-min($D$16:$D$22)) -> 68.214371 | H20: =100*(max($E$16:$E$22)-E20)/(max($E$16:$E$22)-min($E$16:$E$22)) -> 49.995037 | I20: =0.4*F20+0.4*G20+0.2*H20 -> 67.025047 | J20: =IFERROR(__xludf.DUMMYFUNCTION("RANK.EQ(I20,filter(I:I,A:A=A20))"),2.0) -> 2
A21: Corn Starch | B21: PalmEco Corp | C21: 469.57803 | D21: 296.97049 | E21: =countifs('Supply Chain'!D:D,A21,'Supply Chain'!B:B,B21,'Supply Chain'!J:J,2025,'Supply Chain'!K:K,"Y")/countifs('Supply Chain'!D:D,A21,'Supply Chain'!B:B,B21,'Supply Chain'!J:J,2025) -> 0.49180328 | F21: =100*(max($C$16:$C$22)-C21)/(max($C$16:$C$22)-min($C$16:$C$22)) -> 0 | G21: =100*(max($D$16:$D$22)-D21)/(max($D$16:$D$22)-min($D$16:$D$22)) -> 59.214452 | H21: =100*(max($E$16:$E$22)-E21)/(max($E$16:$E$22)-min($E$16:$E$22)) -> 46.290038 | I21: =0.4*F21+0.4*G21+0.2*H21 -> 32.943788 | J21: =IFERROR(__xludf.DUMMYFUNCTION("RANK.EQ(I21,filter(I:I,A:A=A21))"),7.0) -> 7
A22: Corn Starch | B22: SustainSource Inc. | C22: 433.78477 | D22: 315.86818 | E22: =countifs('Supply Chain'!D:D,A22,'Supply Chain'!B:B,B22,'Supply Chain'!J:J,2025,'Supply Chain'!K:K,"Y")/countifs('Supply Chain'!D:D,A22,'Supply Chain'!B:B,B22,'Supply Chain'!J:J,2025) -> 0.59090909 | F22: =100*(max($C$16:$C$22)-C22)/(max($C$16:$C$22)-min($C$16:$C$22)) -> 100 | G22: =100*(max($D$16:$D$22)-D22)/(max($D$16:$D$22)-min($D$16:$D$22)) -> 27.402219 | H22: =100*(max($E$16:$E$22)-E22)/(max($E$16:$E$22)-min($E$16:$E$22)) -> 0 | I22: =0.4*F22+0.4*G22+0.2*H22 -> 50.960888 | J22: =IFERROR(__xludf.DUMMYFUNCTION("RANK.EQ(I22,filter(I:I,A:A=A22))"),4.0) -> 4
A23: Palm Oil Derivative | B23: AgroSource Intl. | C23: 454.16554 | D23: 299.51538 | E23: =countifs('Supply Chain'!D:D,A23,'Supply Chain'!B:B,B23,'Supply Chain'!J:J,2025,'Supply Chain'!K:K,"Y")/countifs('Supply Chain'!D:D,A23,'Supply Chain'!B:B,B23,'Supply Chain'!J:J,2025) -> 0.55384615 | F23: =100*(max($C$23:$C$29)-C23)/(max($C$23:$C$29)-min($C$23:$C$29)) -> 0 | G23: =100*(max($D$23:$D$29)-D23)/(max($D$23:$D$29)-min($D$23:$D$29)) -> 34.686629 | H23: =100*(max($E$23:$E$29)-E23)/(max($E$23:$E$29)-min($E$23:$E$29)) -> 0 | I23: =0.4*F23+0.4*G23+0.2*H23 -> 13.874652 | J23: =IFERROR(__xludf.DUMMYFUNCTION("RANK.EQ(I23,filter(I:I,A:A=A23))"),7.0) -> 7
