Workbook

Sheet Product_Master
A1: SKU_Code | B1: Brand | C1: Category
A2: SKU-POLY-000 | B2: PolyBio | C2: Specialty Polymers
A3: SKU-CARB-001 | B3: CarboLite | C3: Automotive Solutions
A4: SKU-LUBE-002 | B4: LubeX | C4: Automotive Solutions
A5: SKU-THER-003 | B5: ThermoEco | C5: Specialty Polymers
A6: SKU-BIOS-004 | B6: BioSoft | C6: Consumer & Home Care
A7: SKU-CARE-005 | B7: CareFlex | C7: Consumer & Home Care
A8: SKU-NATU-006 | B8: NaturShine | C8: Consumer & Home Care
A9: SKU-TRAN-007 | B9: TransBio | C9: Automotive Solutions
A10: SKU-THER-008 | B10: ThermoEco | C10: Specialty Polymers
A11: SKU-MOTI-009 | B11: MotionEco | C11: Automotive Solutions
A12: SKU-FLEX-010 | B12: FlexiChem | C12: Specialty Polymers
... A751: SKU-GREE-749 | B751: GreenWrap | C751: Packaging Materials

Sheet Sales_Pipeline
A1: SalesOpp_ID | B1: Account_Name | C1: Region | D1: Stage | E1: Close_Date | F1: Product_Interest | G1: Category | H1: Est_Value ($M) | I1: Probability (%) | J1: Weighted Sales Value ($M) | K1: Linked_Project_ID
A2: SO3000 | B2: GlobalGlobal SA | C2: Asia-Pacific | D2: Negotiation | E2: 45711 | F2: GreenWrap | G2: {=XLOOKUP(F2,Product_Master!B:B,Product_Master!C:C,,0)} -> Packaging Materials | H2: 10 | I2: 80 | J2: =H2*I2/100 -> 8
A3: SO3001 | B3: BioSolutions Corp | C3: North America | D3: Closed-Won | E3: 46316 | F3: BioMold | G3: {=XLOOKUP(F3,Product_Master!B:B,Product_Master!C:C,,0)} -> Specialty Polymers | H3: 29.8 | I3: 100 | J3: =H3*I3/100 -> 29.8
A4: SO3002 | B4: IndusSystems Ltd | C4: Asia-Pacific | D4: Negotiation | E4: 46140 | F4: PureClean | G4: {=XLOOKUP(F4,Product_Master!B:B,Product_Master!C:C,,0)} -> Consumer & Home Care | H4: 75 | I4: 80 | J4: =H4*I4/100 -> 60
A5: SO3003 | B5: AutoGlobal GmbH | C5: Europe-Middle East-Africa | D5: Closed-Lost | E5: 46453 | F5: PlantGuard | G5: {=XLOOKUP(F5,Product_Master!B:B,Product_Master!C:C,,0)} -> Industrial Lubricants | H5: 56.9 | I5: 0 | J5: =H5*I5/100 -> 0
A6: SO3004 | B6: IndusGlobal LLC | C6: South America | D6: Proposal Sent | E6: 45855 | F6: PolyBio | G6: {=XLOOKUP(F6,Product_Master!B:B,Product_Master!C:C,,0)} -> Specialty Polymers | H6: 50.8 | I6: 60 | J6: =H6*I6/100 -> 30.48
A7: SO3005 | B7: IndusSystems Ltd | C7: North America | D7: Prospecting | E7: 46809 | F7: CareFlex | G7: {=XLOOKUP(F7,Product_Master!B:B,Product_Master!C:C,,0)} -> Consumer & Home Care | H7: 64.7 | I7: 20 | J7: =H7*I7/100 -> 12.94 | K7: RD0104
A8: SO3006 | B8: PolyMaterials GmbH | C8: South America | D8: Negotiation | E8: 46753 | F8: PureClean | G8: {=XLOOKUP(F8,Product_Master!B:B,Product_Master!C:C,,0)} -> Consumer & Home Care | H8: 28.6 | I8: 80 | J8: =H8*I8/100 -> 22.88
A9: SO3007 | B9: GlobalMaterials SAS | C9: North America | D9: Closed-Lost | E9: 46600 | F9: EcoDrive | G9: {=XLOOKUP(F9,Product_Master!B:B,Product_Master!C:C,,0)} -> Automotive Solutions | H9: 58.3 | I9: 0 | J9: =H9*I9/100 -> 0
A10: SO3008 | B10: TransSolutions LLC | C10: Europe-Middle East-Africa | D10: Closed-Won | E10: 46842 | F10: CareFlex | G10: {=XLOOKUP(F10,Product_Master!B:B,Product_Master!C:C,,0)} -> Consumer & Home Care | H10: 10.6 | I10: 100 | J10: =H10*I10/100 -> 10.6
A11: SO3009 | B11: TransSystems Corp | C11: Europe-Middle East-Africa | D11: Negotiation | E11: 45694 | F11: DuronBio | G11: {=XLOOKUP(F11,Product_Master!B:B,Product_Master!C:C,,0)} -> Specialty Polymers | H11: 15.3 | I11: 80 | J11: =H11*I11/100 -> 12.24
A12: SO3010 | B12: PolyTech Corp | C12: Europe-Middle East-Africa | D12: Negotiation | E12: 45818 | F12: PureClean | G12: {=XLOOKUP(F12,Product_Master!B:B,Product_Master!C:C,,0)} -> Consumer & Home Care | H12: 26 | I12: 80 | J12: =H12*I12/100 -> 20.8
A13: SO3011 | B13: ChemTech SAS | C13: North America | D13: Negotiation | E13: 46525 | F13: PackNatur | G13: {=XLOOKUP(F13,Product_Master!B:B,Product_Master!C:C,,0)} -> Packaging Materials | H13: 53.7 | I13: 80 | J13: =H13*I13/100 -> 42.96
A14: SO3012 | B14: AutoGlobal BV | C14: Europe-Middle East-Africa | D14: Closed-Won | E14: 46461 | F14: EcoFilm | G14: {=XLOOKUP(F14,Product_Master!B:B,Product_Master!C:C,,0)} -> Packaging Materials | H14: 78.8 | I14: 100 | J14: =H14*I14/100 -> 78.8
A15: SO3013 | B15: IndusSolutions BV | C15: North America | D15: Proposal Sent | E15: 46788 | F15: DriveFlex | G15: {=XLOOKUP(F15,Product_Master!B:B,Product_Master!C:C,,0)} -> Automotive Solutions | H15: 9.2 | I15: 60 | J15: =H15*I15/100 -> 5.52
A16: SO3014 | B16: AutoSolutions Corp | C16: North America | D16: Negotiation | E16: 46636 | F16: CarboLite | G16: {=XLOOKUP(F16,Product_Master!B:B,Product_Master!C:C,,0)} -> Automotive Solutions | H16: 73.9 | I16: 80 | J16: =H16*I16/100 -> 59.12
A17: SO3015 | B17: IndusGlobal LLC | C17: Europe-Middle East-Africa | D17: Proposal Sent | E17: 46194 | F17: StrongBio | G17: {=XLOOKUP(F17,Product_Master!B:B,Product_Master!C:C,,0)} -> Specialty Polymers | H17: 58.7 | I17: 60 | J17: =H17*I17/100 -> 35.22
A18: SO3016 | B18: AutoSystems Inc | C18: North America | D18: Prospecting | E18: 46546 | F18: StrongBio | G18: {=XLOOKUP(F18,Product_Master!B:B,Product_Master!C:C,,0)} -> Specialty Polymers | H18: 17.2 | I18: 20 | J18: =H18*I18/100 -> 3.44
A19: SO3017 | B19: ChemSolutions Inc | C19: North America | D19: Prospecting | E19: 45756 | F19: BioMold | G19: {=XLOOKUP(F19,Product_Master!B:B,Product_Master!C:C,,0)} -> Specialty Polymers | H19: 6.6 | I19: 20 | J19: =H19*I19/100 -> 1.32
... A26: SO3024 | B26: AutoGlobal Corp | C26: Europe-Middle East-Africa | D26: Closed-Won | E26: 46829 | F26: GreenFoam | G26: {=XLOOKUP(F26,Product_Master!B:B,Product_Master!C:C,,0)} -> Consumer & Home Care | H26: 15.1 | I26: 100 | J26: =H26*I26/100 -> 15.1
A27: SO3025 | B27: NaturSolutions SA | C27: South America | D27: Negotiation | E27: 45849 | F27: PolyBio | G27: {=XLOOKUP(F27,Product_Master!B:B,Product_Master!C:C,,0)} -> Specialty Polymers | H27: 31.6 | I27: 80 | J27: =H27*I27/100 -> 25.28 | K27: RD0190
A28: SO3026 | B28: PackMaterials Inc | C28: North America | D28: Negotiation | E28: 46460 | F28: CleanWave | G28: {=XLOOKUP(F28,Product_Master!B:B,Product_Master!C:C,,0)} -> Consumer & Home Care | H28: 64.2 | I28: 80 | J28: =H28*I28/100 -> 51.36
A29: SO3027 | B29: PolyTech Ltd | C29: South America | D29: Closed-Lost | E29: 46832 | F29: HomePure | G29: {=XLOOKUP(F29,Product_Master!B:B,Product_Master!C:C,,0)} -> Consumer & Home Care | H29: 72.8 | I29: 0 | J29: =H29*I29/100 -> 0
A30: SO3028 | B30: GlobalSystems SA | C30: North America | D30: Proposal Sent | E30: 46077 | F30: PureClean | G30: {=XLOOKUP(F30,Product_Master!B:B,Product_Master!C:C,,0)} -> Consumer & Home Care | H30: 65.3 | I30: 60 | J30: =H30*I30/100 -> 39.18 | K30: RD0061
A31: SO3029 | B31: TransSolutions Group | C31: South America | D31: Closed-Won | E31: 46178 | F31: FreshBio | G31: {=XLOOKUP(F31,Product_Master!B:B,Product_Master!C:C,,0)} -> Consumer & Home Care | H31: 56 | I31: 100 | J31: =H31*I31/100 -> 56
A32: SO3030 | B32: EcoGlobal SAS | C32: Asia-Pacific | D32: Negotiation | E32: 46223 | F32: EcoWash | G32: {=XLOOKUP(F32,Product_Master!B:B,Product_Master!C:C,,0)} -> Consumer & Home Care | H32: 75.5 | I32: 80 | J32: =H32*I32/100 -> 60.4
A33: SO3031 | B33: TransGlobal Ltd | C33: Europe-Middle East-Africa | D33: Negotiation | E33: 46104 | F33: CareFlex | G33: {=XLOOKUP(F33,Product_Master!B:B,Product_Master!C:C,,0)} -> Consumer & Home Care | H33: 75.6 | I33: 80 | J33: =H33*I33/100 -> 60.48
A34: SO3032 | B34: NaturTech Group | C34: South America | D34: Proposal Sent | E34: 45721 | F34: EcoDrive | G34: {=XLOOKUP(F34,Product_Master!B:B,Product_Master!C:C,,0)} -> Automotive Solutions | H34: 69.1 | I34: 60 | J34: =H34*I34/100 -> 41.46
A35: SO3033 | B35: PolyMaterials PLC | C35: Asia-Pacific | D35: Proposal Sent | E35: 46089 | F35: BioSeal | G35: {=XLOOKUP(F35,Product_Master!B:B,Product_Master!C:C,,0)} -> Automotive Solutions | H35: 71.1 | I35: 60 | J35: =H35*I35/100 -> 42.66
A36: SO3034 | B36: NaturMaterials Inc | C36: Europe-Middle East-Africa | D36: Closed-Lost | E36: 46379 | F36: EcoFilm | G36: {=XLOOKUP(F36,Product_Master!B:B,Product_Master!C:C,,0)} -> Packaging Materials | H36: 9 | I36: 0 | J36: =H36*I36/100 -> 0
A37: SO3035 | B37: TransGlobal SAS | C37: South America | D37: Negotiation | E37: 46034 | F37: GreenFoam | G37: {=XLOOKUP(F37,Product_Master!B:B,Product_Master!C:C,,0)} -> Consumer & Home Care | H37: 6.7 | I37: 80 | J37: =H37*I37/100 -> 5.36
A38: SO3036 | B38: IndusGlobal GmbH | C38: North America | D38: Closed-Lost | E38: 45757 | F38: EcoPack | G38: {=XLOOKUP(F38,Product_Master!B:B,Product_Master!C:C,,0)} -> Packaging Materials | H38: 61.5 | I38: 0 | J38: =H38*I38/100 -> 0
A39: SO3037 | B39: PackTech Corp | C39: Europe-Middle East-Africa | D39: Proposal Sent | E39: 46161 | F39: PolyLite | G39: {=XLOOKUP(F39,Product_Master!B:B,Product_Master!C:C,,0)} -> Packaging Materials | H39: 8.1 | I39: 60 | J39: =H39*I39/100 -> 4.86
A40: SO3038 | B40: AutoTech Inc | C40: Europe-Middle East-Africa | D40: Negotiation | E40: 45811 | F40: EcoPack | G40: {=XLOOKUP(F40,Product_Master!B:B,Product_Master!C:C,,0)} -> Packaging Materials | H40: 78.8 | I40: 80 | J40: =H40*I40/100 -> 63.04
A41: SO3039 | B41: PolyGlobal SAS | C41: North America | D41: Prospecting | E41: 46777 | F41: NaturPoly | G41: {=XLOOKUP(F41,Product_Master!B:B,Product_Master!C:C,,0)} -> Specialty Polymers | H41: 51.7 | I41: 20 | J41: =H41*I41/100 -> 10.34
A42: SO3040 | B42: ChemTech LLC | C42: Asia-Pacific | D42: Closed-Lost | E42: 46275 | F42: LubriGreen | G42: {=XLOOKUP(F42,Product_Master!B:B,Product_Master!C:C,,0)} -> Industrial Lubricants | H42: 28.7 | I42: 0 | J42: =H42*I42/100 -> 0
... A47: SO3045 | B47: ChemTech GmbH | C47: North America | D47: Closed-Won | E47: 46576 | F47: GreenFoam | G47: {=XLOOKUP(F47,Product_Master!B:B,Product_Master!C:C,,0)} -> Consumer & Home Care | H47: 11.8 | I47: 100 | J47: =H47*I47/100 -> 11.8
A48: SO3046 | B48: BioMaterials Ltd | C48: North America | D48: Proposal Sent | E48: 46120 | F48: AutoGuard | G48: {=XLOOKUP(F48,Product_Master!B:B,Product_Master!C:C,,0)} -> Automotive Solutions | H48: 9.3 | I48: 60 | J48: =H48*I48/100 -> 5.58 | K48: RD0291
A49: SO3047 | B49: TransSystems Corp | C49: North America | D49: Negotiation | E49: 46800 | F49: NaturShine | G49: {=XLOOKUP(F49,Product_Master!B:B,Product_Master!C:C,,0)} -> Consumer & Home Care | H49: 19.7 | I49: 80 | J49: =H49*I49/100 -> 15.76
A50: SO3048 | B50: ChemSolutions BV | C50: North America | D50: Proposal Sent | E50: 45983 | F50: CareFlex | G50: {=XLOOKUP(F50,Product_Master!B:B,Product_Master!C:C,,0)} -> Consumer & Home Care | H50: 29.2 | I50: 60 | J50: =H50*I50/100 -> 17.52
...

Sheet RD_Pipeline
A1: Project_ID | B1: Project_Name | C1: Stage | D1: Est_Launch_Date | E1: Project_Manager | F1: Target_Industry | G1: Est_Annual_Revenue ($M) | H1: Linked_SalesOpp_ID | I1: Category
A2: RD0001 | B2: Project Sticky Tape | C2: 3-Customer & Regulatory Sampling | D2: 46569 | E2: Chen Wei | F2: Packaging Materials | G2: 40.6 | H2: SO5204 | I2: {=XLOOKUP(H2, Sales_Pipeline!A:A, Sales_Pipeline!G:G, "Not Found")} -> Industrial Lubricants
A3: RD0002 | B3: Project MegaMold | C3: 5-Scale-up | D3: 47596 | E3: Emma Johansson | F3: Consumer & Home Care | G3: 95.3 | H3: SO4999 | I3: {=XLOOKUP(H3, Sales_Pipeline!A:A, Sales_Pipeline!G:G, "Not Found")} -> Specialty Polymers
A4: RD0003 | B4: Project Slippery Fish | C4: 3-Customer & Regulatory Sampling | D4: 46850 | E4: Fatima Al-Sayed | F4: Automotive Solutions | G4: 74.5 | H4: SO4592 | I4: {=XLOOKUP(H4, Sales_Pipeline!A:A, Sales_Pipeline!G:G, "Not Found")} -> Automotive Solutions
A5: RD0004 | B5: Project Bouncy Ball | C5: 4-Manufacturing Trials | D5: 47441 | E5: Ayumi Nakamura | F5: Packaging Materials | G5: 61.9 | H5: SO3522 | I5: {=XLOOKUP(H5, Sales_Pipeline!A:A, Sales_Pipeline!G:G, "Not Found")} -> Industrial Lubricants
A6: RD0005 | B6: Project SuperGlue | C6: 5-Scale-up | D6: 46013 | E6: Chen Wei | F6: Specialty Polymers | G6: 19.8 | H6: SO5311 | I6: {=XLOOKUP(H6, Sales_Pipeline!A:A, Sales_Pipeline!G:G, "Not Found")} -> Automotive Solutions
A7: RD0006 | B7: Project MegaMold | C7: 1-Material Discovery | D7: 46129 | E7: Chen Wei | F7: Consumer & Home Care | G7: 19.8 | H7: SO4891 | I7: {=XLOOKUP(H7, Sales_Pipeline!A:A, Sales_Pipeline!G:G, "Not Found")} -> Consumer & Home Care
A8: RD0007 | B8: Project Slippery Fish | C8: 1-Material Discovery | D8: 46490 | E8: Chen Wei | F8: Industrial Lubricants | G8: 10.5 | H8: SO3866 | I8: {=XLOOKUP(H8, Sales_Pipeline!A:A, Sales_Pipeline!G:G, "Not Found")} -> Specialty Polymers
A9: RD0008 | B9: Project SlickRoad | C9: 3-Customer & Regulatory Sampling | D9: 46649 | E9: Chen Wei | F9: Industrial Lubricants | G9: 87.3 | H9: SO4726 | I9: {=XLOOKUP(H9, Sales_Pipeline!A:A, Sales_Pipeline!G:G, "Not Found")} -> Specialty Polymers
A10: RD0009 | B10: Project Bouncy Ball | C10: 1-Material Discovery | D10: 46921 | E10: Maria Lopez | F10: Specialty Polymers | G10: 62.1 | H10: SO3213 | I10: {=XLOOKUP(H10, Sales_Pipeline!A:A, Sales_Pipeline!G:G, "Not Found")} -> Consumer & Home Care
A11: RD0010 | B11: Project Bouncy Ball | C11: 2-Lab Tests | D11: 47289 | E11: Raj Patel | F11: Automotive Solutions | G11: 72.3 | H11: SO3127 | I11: {=XLOOKUP(H11, Sales_Pipeline!A:A, Sales_Pipeline!G:G, "Not Found")} -> Automotive Solutions
A12: RD0011 | B12: Project Slippery Fish | C12: 2-Lab Tests | D12: 45999 | E12: Emma Johansson | F12: Consumer & Home Care | G12: 7 | H12: SO3977 | I12: {=XLOOKUP(H12, Sales_Pipeline!A:A, Sales_Pipeline!G:G, "Not Found")} -> Consumer & Home Care
A13: RD0012 | B13: Project Slippery Fish | C13: 4-Manufacturing Trials | D13: 47329 | E13: Raj Patel | F13: Specialty Polymers | G13: 97.1 | H13: SO3892 | I13: {=XLOOKUP(H13, Sales_Pipeline!A:A, Sales_Pipeline!G:G, "Not Found")} -> Packaging Materials
... A313: RD0312 | B313: Project SlickRoad | C313: 3-Customer & Regulatory Sampling | D313: 46466 | E313: Maria Lopez | F313: Industrial Lubricants | G313: 12.5 | H313: SO4571 | I313: {=XLOOKUP(H313, Sales_Pipeline!A:A, Sales_Pipeline!G:G, "Not Found")} -> Consumer & Home Care

Sheet Pivot Table 1

Sheet Category Summary
A1: Category | B1: Weighted Sales ($M) non-lost stage | C1: Weighted Sales ($M) Closed-Won | D1: Total R&D Value ($M)
A2: Consumer & Home Care | B2: =SUMIFS(Sales_Pipeline!J:J,Sales_Pipeline!G:G,A2,Sales_Pipeline!I:I,"<>0") -> 14144.54 | C2: =SUMIFS(Sales_Pipeline!$J:$J, Sales_Pipeline!$G:$G, A2, Sales_Pipeline!$D:$D, "Closed-Won") -> 5942.6 | D2: =SUMIF(RD_Pipeline!$F:$F,A2,RD_Pipeline!$G:$G) -> 3614.2
A3: Automotive Solutions | B3: =SUMIFS(Sales_Pipeline!J:J,Sales_Pipeline!G:G,A3,Sales_Pipeline!I:I,"<>0") -> 13996.24 | C3: =SUMIFS(Sales_Pipeline!$J:$J, Sales_Pipeline!$G:$G, A3, Sales_Pipeline!$D:$D, "Closed-Won") -> 5153.4 | D3: =SUMIF(RD_Pipeline!$F:$F,A3,RD_Pipeline!$G:$G) -> 2732.4
A4: Industrial Lubricants | B4: =SUMIFS(Sales_Pipeline!J:J,Sales_Pipeline!G:G,A4,Sales_Pipeline!I:I,"<>0") -> 13609.18 | C4: =SUMIFS(Sales_Pipeline!$J:$J, Sales_Pipeline!$G:$G, A4, Sales_Pipeline!$D:$D, "Closed-Won") -> 5630.7 | D4: =SUMIF(RD_Pipeline!$F:$F,A4,RD_Pipeline!$G:$G) -> 3812.3
A5: Specialty Polymers | B5: =SUMIFS(Sales_Pipeline!J:J,Sales_Pipeline!G:G,A5,Sales_Pipeline!I:I,"<>0") -> 12629.02 | C5: =SUMIFS(Sales_Pipeline!$J:$J, Sales_Pipeline!$G:$G, A5, Sales_Pipeline!$D:$D, "Closed-Won") -> 4442 | D5: =SUMIF(RD_Pipeline!$F:$F,A5,RD_Pipeline!$G:$G) -> 3004.5
A6: Packaging Materials | B6: =SUMIFS(Sales_Pipeline!J:J,Sales_Pipeline!G:G,A6,Sales_Pipeline!I:I,"<>0") -> 11861.38 | C6: =SUMIFS(Sales_Pipeline!$J:$J, Sales_Pipeline!$G:$G, A6, Sales_Pipeline!$D:$D, "Closed-Won") -> 5124.9 | D6: =SUMIF(RD_Pipeline!$F:$F,A6,RD_Pipeline!$G:$G) -> 3069.3
A8: For Sales | B8: For Closed-Won Sales
A9: Highest: 14,144.54M | B9: Highest: 5,942.6M
A10: Lowest: 11,861.38M | B10: Lowest: 4,442.0M
A12: Spread: $2.28B (only 16%) | B12: Spread: $1.50B (≈27%)
A13: This means all five categories show meaningful commercial opportunity.
A14: No category is “dead” or irrelevant — the sales pipeline is well-distributed. | B14: This indicates that Closed-Won demand is moderately concentrated, with the top category outperforming the lowest by nearly $1.5B.
B15: Unlike the total sales pipeline (which was evenly distributed), the actual won business shows clearer winners and weaker categories.
A17: For R&D | B17: This means:
A18: Highest: 3,812.3M | B18: Some categories are driving significantly more realized revenue than others.
A19: Lowest: 2,732.4M | B19: Market traction is not uniform, customer conversion differs by category.
B20: Strategic prioritization should focus on the top-performing categories that consistently convert.
A21: Spread: $1.08B (only 7–8%) | B21: This distribution is meaningful, it highlights where the company is actually winning, not just where opportunities exist.
A22: → R&D is distributed more evenly than sales opportunity.
A23: This proves R&D strategy is not market-driven.
A24: Industrial Lubricants → High R&D, mid Sales
A25: Automotive Solutions → High Sales, low R&D
A26: Packaging Materials → Lower Sales, medium R&D
A27: Consumer & Home Care → Highest Sales, middle R&D
A28: This misalignment reduces ROI on innovation.
