Workbook

Sheet Supply Chain
A1: PO_Number | B1: Supplier_Name | C1: Material_Code | D1: RawMaterial_Name | E1: Qty (MT) | F1: Unit_Cost ($) | G1: Country_Origin | H1: Delivery_Date | I1: Delivery_Month | J1: Delivery_Yr | K1: On_Time (Y/N) | L1: CO2_Emissions (kg/MT) | M1: Total MT Cost ($) | N1: Total Emissions (kg)
A2: PUR2000 | B2: EcoMaterials Co. | C2: RM-0000 | D2: Sugarcane Fiber | E2: 669 | F2: 301.56 | G2: Germany | H2: 45838 | I2: 6 | J2: 2025 | K2: N | L2: 116.8 | M2: 201743.64 | N2: 78139.2
A3: PUR2001 | B3: NaturInput GmbH | C3: RM-0001 | D3: Palm Oil Derivative | E3: 820 | F3: 338.39 | G3: India | H3: 45870 | I3: 8 | J3: 2025 | K3: Y | L3: 492.6 | M3: 277479.8 | N3: 403932
A4: PUR2002 | B4: BioFeedstock Ltd. | C4: RM-0002 | D4: Algae Oil | E4: 514 | F4: 502.61 | G4: Germany | H4: 45969 | I4: 11 | J4: 2025 | K4: N | L4: 350.9 | M4: 258341.54 | N4: 180362.6
A5: PUR2003 | B5: PalmEco Corp | C5: RM-0003 | D5: Sugarcane Fiber | E5: 854 | F5: 450.71 | G5: China | H5: 45917 | I5: 9 | J5: 2025 | K5: Y | L5: 313.9 | M5: 384906.34 | N5: 268070.6
A6: PUR2004 | B6: AgroSource Intl. | C6: RM-0004 | D6: Algae Oil | E6: 120 | F6: 542.47 | G6: Indonesia | H6: 45766 | I6: 4 | J6: 2025 | K6: Y | L6: 283.5 | M6: 65096.4 | N6: 34020
A7: PUR2005 | B7: BioFeedstock Ltd. | C7: RM-0005 | D7: Algae Oil | E7: 211 | F7: 408 | G7: Malaysia | H7: 46015 | I7: 12 | J7: 2025 | K7: Y | L7: 322.6 | M7: 86088 | N7: 68068.6
A8: PUR2006 | B8: AgroSource Intl. | C8: RM-0006 | D8: Cassava Starch | E8: 218 | F8: 552.58 | G8: Malaysia | H8: 45987 | I8: 11 | J8: 2025 | K8: Y | L8: 295.8 | M8: 120462.44 | N8: 64484.4
A9: PUR2409 | B9: AgroSource Intl. | C9: RM-0409 | D9: Algae Oil | E9: 472 | F9: 522.8 | G9: Brazil | H9: 45986 | I9: 11 | J9: 2025 | K9: Y | L9: 391.6 | M9: 246761.6 | N9: 184835.2
A10: PUR2008 | B10: PalmEco Corp | C10: RM-0008 | D10: Cassava Starch | E10: 963 | F10: 389.65 | G10: India | H10: 46014 | I10: 12 | J10: 2025 | K10: Y | L10: 267.2 | M10: 375232.95 | N10: 257313.6
A11: PUR2009 | B11: AgroSource Intl. | C11: RM-0009 | D11: Sugarcane Fiber | E11: 770 | F11: 534.75 | G11: Malaysia | H11: 46011 | I11: 12 | J11: 2025 | K11: Y | L11: 387.7 | M11: 411757.5 | N11: 298529
A12: PUR2010 | B12: BioFeedstock Ltd. | C12: RM-0010 | D12: Corn Starch | E12: 637 | F12: 509.81 | G12: Indonesia | H12: 45781 | I12: 5 | J12: 2025 | K12: Y | L12: 419.9 | M12: 324748.97 | N12: 267476.3
A13: PUR2011 | B13: BioFeedstock Ltd. | C13: RM-0011 | D13: Algae Oil | E13: 523 | F13: 411.1 | G13: Indonesia | H13: 45927 | I13: 9 | J13: 2025 | K13: N | L13: 170 | M13: 215005.3 | N13: 88910
... A2891: PUR4889 | B2891: EcoMaterials Co. | C2891: RM-2889 | D2891: Wood Pulp | E2891: 118 | F2891: 402.01 | G2891: USA | H2891: 45723 | I2891: 3 | J2891: 2025 | K2891: N | L2891: 430.6 | M2891: 47437.18 | N2891: 50810.8

Sheet SSI
A1: RawMaterial_Name | B1: Supplier_Name | C1: AVERAGE of Unit_Cost ($) | D1: AVERAGE of CO2_Emissions (kg/MT) | E1: Delivery Rate | F1: Cost Score | G1: CO2 Score | H1: Deliver Score | I1: SSI (100) | J1: Rank
A2: Algae Oil | B2: AgroSource Intl. | C2: 460.6764 | D2: 320.032 | E2: =countifs('Supply Chain'!D:D,A2,'Supply Chain'!B:B,B2,'Supply Chain'!J:J,2025,'Supply Chain'!K:K,"Y")/countifs('Supply Chain'!D:D,A2,'Supply Chain'!B:B,B2,'Supply Chain'!J:J,2025) -> 0.46 | F2: =100*(max($C$2:$C$8)-C2)/(max($C$2:$C$8)-min($C$2:$C$8)) -> 11.465946 | G2: =100*(max($D$2:$D$8)-D2)/(max($D$2:$D$8)-min($D$2:$D$8)) -> 34.185532 | H2: =100*(max($E$2:$E$8)-E2)/(max($E$2:$E$8)-min($E$2:$E$8)) -> 39.710396 | I2: =0.4*F2+0.4*G2+0.2*H2 -> 26.20267 | J2: =IFERROR(__xludf.DUMMYFUNCTION("RANK.EQ(I2,filter(I:I,A:A=A2))"),7.0) -> 7
A3: Algae Oil | B3: BioFeedstock Ltd. | C3: 440.32173 | D3: 336.23077 | E3: =countifs('Supply Chain'!D:D,A3,'Supply Chain'!B:B,B3,'Supply Chain'!J:J,2025,'Supply Chain'!K:K,"Y")/countifs('Supply Chain'!D:D,A3,'Supply Chain'!B:B,B3,'Supply Chain'!J:J,2025) -> 0.51923077 | F3: =100*(max($C$2:$C$8)-C3)/(max($C$2:$C$8)-min($C$2:$C$8)) -> 97.331759 | G3: =100*(max($D$2:$D$8)-D3)/(max($D$2:$D$8)-min($D$2:$D$8)) -> 0 | H3: =100*(max($E$2:$E$8)-E3)/(max($E$2:$E$8)-min($E$2:$E$8)) -> 8.85615 | I3: =0.4*F3+0.4*G3+0.2*H3 -> 40.703934 | J3: =IFERROR(__xludf.DUMMYFUNCTION("RANK.EQ(I3,filter(I:I,A:A=A3))"),5.0) -> 5
A4: Algae Oil | B4: EcoMaterials Co. | C4: 452.54902 | D4: 304.38852 | E4: =countifs('Supply Chain'!D:D,A4,'Supply Chain'!B:B,B4,'Supply Chain'!J:J,2025,'Supply Chain'!K:K,"Y")/countifs('Supply Chain'!D:D,A4,'Supply Chain'!B:B,B4,'Supply Chain'!J:J,2025) -> 0.49180328 | F4: =100*(max($C$2:$C$8)-C4)/(max($C$2:$C$8)-min($C$2:$C$8)) -> 45.75117 | G4: =100*(max($D$2:$D$8)-D4)/(max($D$2:$D$8)-min($D$2:$D$8)) -> 67.199185 | H4: =100*(max($E$2:$E$8)-E4)/(max($E$2:$E$8)-min($E$2:$E$8)) -> 23.143564 | I4: =0.4*F4+0.4*G4+0.2*H4 -> 49.808855 | J4: =IFERROR(__xludf.DUMMYFUNCTION("RANK.EQ(I4,filter(I:I,A:A=A4))"),4.0) -> 4
A5: Algae Oil | B5: GreenFibre BV | C5: 445.46132 | D5: 315.14265 | E5: =countifs('Supply Chain'!D:D,A5,'Supply Chain'!B:B,B5,'Supply Chain'!J:J,2025,'Supply Chain'!K:K,"Y")/countifs('Supply Chain'!D:D,A5,'Supply Chain'!B:B,B5,'Supply Chain'!J:J,2025) -> 0.38235294 | F5: =100*(max($C$2:$C$8)-C5)/(max($C$2:$C$8)-min($C$2:$C$8)) -> 75.650478 | G5: =100*(max($D$2:$D$8)-D5)/(max($D$2:$D$8)-min($D$2:$D$8)) -> 44.503917 | H5: =100*(max($E$2:$E$8)-E5)/(max($E$2:$E$8)-min($E$2:$E$8)) -> 80.157979 | I5: =0.4*F5+0.4*G5+0.2*H5 -> 64.093354 | J5: =IFERROR(__xludf.DUMMYFUNCTION("RANK.EQ(I5,filter(I:I,A:A=A5))"),1.0) -> 1
A6: Algae Oil | B6: NaturInput GmbH | C6: 439.68922 | D6: 328.12969 | E6: =countifs('Supply Chain'!D:D,A6,'Supply Chain'!B:B,B6,'Supply Chain'!J:J,2025,'Supply Chain'!K:K,"Y")/countifs('Supply Chain'!D:D,A6,'Supply Chain'!B:B,B6,'Supply Chain'!J:J,2025) -> 0.40625 | F6: =100*(max($C$2:$C$8)-C6)/(max($C$2:$C$8)-min($C$2:$C$8)) -> 100 | G6: =100*(max($D$2:$D$8)-D6)/(max($D$2:$D$8)-min($D$2:$D$8)) -> 17.096348 | H6: =100*(max($E$2:$E$8)-E6)/(max($E$2:$E$8)-min($E$2:$E$8)) -> 67.709623 | I6: =0.4*F6+0.4*G6+0.2*H6 -> 60.380464 | J6: =IFERROR(__xludf.DUMMYFUNCTION("RANK.EQ(I6,filter(I:I,A:A=A6))"),2.0) -> 2
A7: Algae Oil | B7: PalmEco Corp | C7: 463.39443 | D7: 288.8459 | E7: =countifs('Supply Chain'!D:D,A7,'Supply Chain'!B:B,B7,'Supply Chain'!J:J,2025,'Supply Chain'!K:K,"Y")/countifs('Supply Chain'!D:D,A7,'Supply Chain'!B:B,B7,'Supply Chain'!J:J,2025) -> 0.3442623 | F7: =100*(max($C$2:$C$8)-C7)/(max($C$2:$C$8)-min($C$2:$C$8)) -> 0 | G7: =100*(max($D$2:$D$8)-D7)/(max($D$2:$D$8)-min($D$2:$D$8)) -> 100 | H7: =100*(max($E$2:$E$8)-E7)/(max($E$2:$E$8)-min($E$2:$E$8)) -> 100 | I7: =0.4*F7+0.4*G7+0.2*H7 -> 60 | J7: =IFERROR(__xludf.DUMMYFUNCTION("RANK.EQ(I7,filter(I:I,A:A=A7))"),3.0) -> 3
A8: Algae Oil | B8: SustainSource Inc. | C8: 454.82623 | D8: 309.27681 | E8: =countifs('Supply Chain'!D:D,A8,'Supply Chain'!B:B,B8,'Supply Chain'!J:J,2025,'Supply Chain'!K:K,"Y")/countifs('Supply Chain'!D:D,A8,'Supply Chain'!B:B,B8,'Supply Chain'!J:J,2025) -> 0.53623188 | F8: =100*(max($C$2:$C$8)-C8)/(max($C$2:$C$8)-min($C$2:$C$8)) -> 36.144777 | G8: =100*(max($D$2:$D$8)-D8)/(max($D$2:$D$8)-min($D$2:$D$8)) -> 56.883049 | H8: =100*(max($E$2:$E$8)-E8)/(max($E$2:$E$8)-min($E$2:$E$8)) -> 0 | I8: =0.4*F8+0.4*G8+0.2*H8 -> 37.211131 | J8: =IFERROR(__xludf.DUMMYFUNCTION("RANK.EQ(I8,filter(I:I,A:A=A8))"),6.0) -> 6
A9: Cassava Starch | B9: AgroSource Intl. | C9: 448.1788 | D9: 300.304 | E9: =countifs('Supply Chain'!D:D,A9,'Supply Chain'!B:B,B9,'Supply Chain'!J:J,2025,'Supply Chain'!K:K,"Y")/countifs('Supply Chain'!D:D,A9,'Supply Chain'!B:B,B9,'Supply Chain'!J:J,2025) -> 0.46666667 | F9: =100*(max($C$9:$C$15)-C9)/(max($C$9:$C$15)-min($C$9:$C$15)) -> 45.233345 | G9: =100*(max($D$9:$D$15)-D9)/(max($D$9:$D$15)-min($D$9:$D$15)) -> 72.269697 | H9: =100*(max($E$9:$E$15)-E9)/(max($E$9:$E$15)-min($E$9:$E$15)) -> 63.485035 | I9: =0.4*F9+0.4*G9+0.2*H9 -> 59.698224 | J9: =IFERROR(__xludf.DUMMYFUNCTION("RANK.EQ(I9,filter(I:I,A:A=A9))"),3.0) -> 3
A10: Cassava Starch | B10: BioFeedstock Ltd. | C10: 447.59151 | D10: 319.62264 | E10: =countifs('Supply Chain'!D:D,A10,'Supply Chain'!B:B,B10,'Supply Chain'!J:J,2025,'Supply Chain'!K:K,"Y")/countifs('Supply Chain'!D:D,A10,'Supply Chain'!B:B,B10,'Supply Chain'!J:J,2025) -> 0.45283019 | F10: =100*(max($C$9:$C$15)-C10)/(max($C$9:$C$15)-min($C$9:$C$15)) -> 46.629037 | G10: =100*(max($D$9:$D$15)-D10)/(max($D$9:$D$15)-min($D$9:$D$15)) -> 30.788362 | H10: =100*(max($E$9:$E$15)-E10)/(max($E$9:$E$15)-min($E$9:$E$15)) -> 68.572025 | I10: =0.4*F10+0.4*G10+0.2*H10 -> 44.681365 | J10: =IFERROR(__xludf.DUMMYFUNCTION("RANK.EQ(I10,filter(I:I,A:A=A10))"),6.0) -> 6
A11: Cassava Starch | B11: EcoMaterials Co. | C11: 435.64735 | D11: 289.10408 | E11: =countifs('Supply Chain'!D:D,A11,'Supply Chain'!B:B,B11,'Supply Chain'!J:J,2025,'Supply Chain'!K:K,"Y")/countifs('Supply Chain'!D:D,A11,'Supply Chain'!B:B,B11,'Supply Chain'!J:J,2025) -> 0.36734694 | F11: =100*(max($C$9:$C$15)-C11)/(max($C$9:$C$15)-min($C$9:$C$15)) -> 75.014247 | G11: =100*(max($D$9:$D$15)-D11)/(max($D$9:$D$15)-min($D$9:$D$15)) -> 96.318363 | H11: =100*(max($E$9:$E$15)-E11)/(max($E$9:$E$15)-min($E$9:$E$15)) -> 100 | I11: =0.4*F11+0.4*G11+0.2*H11 -> 88.533044 | J11: =IFERROR(__xludf.DUMMYFUNCTION("RANK.EQ(I11,filter(I:I,A:A=A11))"),1.0) -> 1
A12: Cassava Starch | B12: GreenFibre BV | C12: 447.1883 | D12: 311.89057 | E12: =countifs('Supply Chain'!D:D,A12,'Supply Chain'!B:B,B12,'Supply Chain'!J:J,2025,'Supply Chain'!K:K,"Y")/countifs('Supply Chain'!D:D,A12,'Supply Chain'!B:B,B12,'Supply Chain'!J:J,2025) -> 0.45283019 | F12: =100*(max($C$9:$C$15)-C12)/(max($C$9:$C$15)-min($C$9:$C$15)) -> 47.587256 | G12: =100*(max($D$9:$D$15)-D12)/(max($D$9:$D$15)-min($D$9:$D$15)) -> 47.390814 | H12: =100*(max($E$9:$E$15)-E12)/(max($E$9:$E$15)-min($E$9:$E$15)) -> 68.572025 | I12: =0.4*F12+0.4*G12+0.2*H12 -> 51.705633 | J12: =IFERROR(__xludf.DUMMYFUNCTION("RANK.EQ(I12,filter(I:I,A:A=A12))"),4.0) -> 4
A13: Cassava Starch | B13: NaturInput GmbH | C13: 455.7693 | D13: 287.38947 | E13: =countifs('Supply Chain'!D:D,A13,'Supply Chain'!B:B,B13,'Supply Chain'!J:J,2025,'Supply Chain'!K:K,"Y")/countifs('Supply Chain'!D:D,A13,'Supply Chain'!B:B,B13,'Supply Chain'!J:J,2025) -> 0.50877193 | F13: =100*(max($C$9:$C$15)-C13)/(max($C$9:$C$15)-min($C$9:$C$15)) -> 27.194584 | G13: =100*(max($D$9:$D$15)-D13)/(max($D$9:$D$15)-min($D$9:$D$15)) -> 100 | H13: =100*(max($E$9:$E$15)-E13)/(max($E$9:$E$15)-min($E$9:$E$15)) -> 48.005006 | I13: =0.4*F13+0.4*G13+0.2*H13 -> 60.478835 | J13: =IFERROR(__xludf.DUMMYFUNCTION("RANK.EQ(I13,filter(I:I,A:A=A13))"),2.0) -> 2
A14: Cassava Starch | B14: PalmEco Corp | C14: 425.13364 | D14: 333.96136 | E14: =countifs('Supply Chain'!D:D,A14,'Supply Chain'!B:B,B14,'Supply Chain'!J:J,2025,'Supply Chain'!K:K,"Y")/countifs('Supply Chain'!D:D,A14,'Supply Chain'!B:B,B14,'Supply Chain'!J:J,2025) -> 0.52272727 | F14: =100*(max($C$9:$C$15)-C14)/(max($C$9:$C$15)-min($C$9:$C$15)) -> 100 | G14: =100*(max($D$9:$D$15)-D14)/(max($D$9:$D$15)-min($D$9:$D$15)) -> 0 | H14: =100*(max($E$9:$E$15)-E14)/(max($E$9:$E$15)-min($E$9:$E$15)) -> 42.874315 | I14: =0.4*F14+0.4*G14+0.2*H14 -> 48.574863 | J14: =IFERROR(__xludf.DUMMYFUNCTION("RANK.EQ(I14,filter(I:I,A:A=A14))"),5.0) -> 5
A15: Cassava Starch | B15: SustainSource Inc. | C15: 467.21246 | D15: 298.8541 | E15: =countifs('Supply Chain'!D:D,A15,'Supply Chain'!B:B,B15,'Supply Chain'!J:J,2025,'Supply Chain'!K:K,"Y")/countifs('Supply Chain'!D:D,A15,'Supply Chain'!B:B,B15,'Supply Chain'!J:J,2025) -> 0.63934426 | F15: =100*(max($C$9:$C$15)-C15)/(max($C$9:$C$15)-min($C$9:$C$15)) -> 0 | G15: =100*(max($D$9:$D$15)-D15)/(max($D$9:$D$15)-min($D$9:$D$15)) -> 75.382952 | H15: =100*(max($E$9:$E$15)-E15)/(max($E$9:$E$15)-min($E$9:$E$15)) -> 0 | I15: =0.4*F15+0.4*G15+0.2*H15 -> 30.153181 | J15: =IFERROR(__xludf.DUMMYFUNCTION("RANK.EQ(I15,filter(I:I,A:A=A15))"),7.0) -> 7
A16: Corn Starch | B16: AgroSource Intl. | C16: 438.16385 | D16: 332.14615 | E16: =countifs('Supply Chain'!D:D,A16,'Supply Chain'!B:B,B16,'Supply Chain'!J:J,2025,'Supply Chain'!K:K,"Y")/countifs('Supply Chain'!D:D,A16,'Supply Chain'!B:B,B16,'Supply Chain'!J:J,2025) -> 0.46153846 | F16: =100*(max($C$16:$C$22)-C16)/(max($C$16:$C$22)-min($C$16:$C$22)) -> 87.765648 | G16: =100*(max($D$16:$D$22)-D16)/(max($D$16:$D$22)-min($D$16:$D$22)) -> 0 | H16: =100*(max($E$16:$E$22)-E16)/(max($E$16:$E$22)-min($E$16:$E$22)) -> 60.426035 | I16: =0.4*F16+0.4*G16+0.2*H16 -> 47.191466 | J16: =IFERROR(__xludf.DUMMYFUNCTION("RANK.EQ(I16,filter(I:I,A:A=A16))"),6.0) -> 6
A17: Corn Starch | B17: BioFeedstock Ltd. | C17: 440.74942 | D17: 328.74783 | E17: =countifs('Supply Chain'!D:D,A17,'Supply Chain'!B:B,B17,'Supply Chain'!J:J,2025,'Supply Chain'!K:K,"Y")/countifs('Supply Chain'!D:D,A17,'Supply Chain'!B:B,B17,'Supply Chain'!J:J,2025) -> 0.37681159 | F17: =100*(max($C$16:$C$22)-C17)/(max($C$16:$C$22)-min($C$16:$C$22)) -> 80.542014 | G17: =100*(max($D$16:$D$22)-D17)/(max($D$16:$D$22)-min($D$16:$D$22)) -> 5.7207201 | H17: =100*(max($E$16:$E$22)-E17)/(max($E$16:$E$22)-min($E$16:$E$22)) -> 100 | I17: =0.4*F17+0.4*G17+0.2*H17 -> 54.505094 | J17: =IFERROR(__xludf.DUMMYFUNCTION("RANK.EQ(I17,filter(I:I,A:A=A17))"),3.0) -> 3
A18: Corn Starch | B18: EcoMaterials Co. | C18: 433.89846 | D18: 272.74231 | E18: =countifs('Supply Chain'!D:D,A18,'Supply Chain'!B:B,B18,'Supply Chain'!J:J,2025,'Supply Chain'!K:K,"Y")/countifs('Supply Chain'!D:D,A18,'Supply Chain'!B:B,B18,'Supply Chain'!J:J,2025) -> 0.48076923 | F18: =100*(max($C$16:$C$22)-C18)/(max($C$16:$C$22)-min($C$16:$C$22)) -> 99.682374 | G18: =100*(max($D$16:$D$22)-D18)/(max($D$16:$D$22)-min($D$16:$D$22)) -> 100 | H18: =100*(max($E$16:$E$22)-E18)/(max($E$16:$E$22)-min($E$16:$E$22)) -> 51.443787 | I18: =0.4*F18+0.4*G18+0.2*H18 -> 90.161707 | J18: =IFERROR(__xludf.DUMMYFUNCTION("RANK.EQ(I18,filter(I:I,A:A=A18))"),1.0) -> 1
A19: Corn Starch | B19: GreenFibre BV | C19: 457.05662 | D19: 292.39385 | E19: =countifs('Supply Chain'!D:D,A19,'Supply Chain'!B:B,B19,'Supply Chain'!J:J,2025,'Supply Chain'!K:K,"Y")/countifs('Supply Chain'!D:D,A19,'Supply Chain'!B:B,B19,'Supply Chain'!J:J,2025) -> 0.49230769 | F19: =100*(max($C$16:$C$22)-C19)/(max($C$16:$C$22)-min($C$16:$C$22)) -> 34.982612 | G19: =100*(max($D$16:$D$22)-D19)/(max($D$16:$D$22)-min($D$16:$D$22)) -> 66.918744 | H19: =100*(max($E$16:$E$22)-E19)/(max($E$16:$E$22)-min($E$16:$E$22)) -> 46.054438 | I19: =0.4*F19+0.4*G19+0.2*H19 -> 49.97143 | J19: =IFERROR(__xludf.DUMMYFUNCTION("RANK.EQ(I19,filter(I:I,A:A=A19))"),5.0) -> 5
A20: Corn Starch | B20: NaturInput GmbH | C20: 442.96548 | D20: 291.62419 | E20: =countifs('Supply Chain'!D:D,A20,'Supply Chain'!B:B,B20,'Supply Chain'!J:J,2025,'Supply Chain'!K:K,"Y")/countifs('Supply Chain'!D:D,A20,'Supply Chain'!B:B,B20,'Supply Chain'!J:J,2025) -> 0.48387097 | F20: =100*(max($C$16:$C$22)-C20)/(max($C$16:$C$22)-min($C$16:$C$22)) -> 74.350727 | G20: =100*(max($D$16:$D$22)-D20)/(max($D$16:$D$22)-min($D$16:$D$22)) -> 68.214371 | H20: =100*(max($E$16:$E$22)-E20)/(max($E$16:$E$22)-min($E$16:$E$22)) -> 49.995037 | I20: =0.4*F20+0.4*G20+0.2*H20 -> 67.025047 | J20: =IFERROR(__xludf.DUMMYFUNCTION("RANK.EQ(I20,filter(I:I,A:A=A20))"),2.0) -> 2
A21: Corn Starch | B21: PalmEco Corp | C21: 469.57803 | D21: 296.97049 | E21: =countifs('Supply Chain'!D:D,A21,'Supply Chain'!B:B,B21,'Supply Chain'!J:J,2025,'Supply Chain'!K:K,"Y")/countifs('Supply Chain'!D:D,A21,'Supply Chain'!B:B,B21,'Supply Chain'!J:J,2025) -> 0.49180328 | F21: =100*(max($C$16:$C$22)-C21)/(max($C$16:$C$22)-min($C$16:$C$22)) -> 0 | G21: =100*(max($D$16:$D$22)-D21)/(max($D$16:$D$22)-min($D$16:$D$22)) -> 59.214452 | H21: =100*(max($E$16:$E$22)-E21)/(max($E$16:$E$22)-min($E$16:$E$22)) -> 46.290038 | I21: =0.4*F21+0.4*G21+0.2*H21 -> 32.943788 | J21: =IFERROR(__xludf.DUMMYFUNCTION("RANK.EQ(I21,filter(I:I,A:A=A21))"),7.0) -> 7
A22: Corn Starch | B22: SustainSource Inc. | C22: 433.78477 | D22: 315.86818 | E22: =countifs('Supply Chain'!D:D,A22,'Supply Chain'!B:B,B22,'Supply Chain'!J:J,2025,'Supply Chain'!K:K,"Y")/countifs('Supply Chain'!D:D,A22,'Supply Chain'!B:B,B22,'Supply Chain'!J:J,2025) -> 0.59090909 | F22: =100*(max($C$16:$C$22)-C22)/(max($C$16:$C$22)-min($C$16:$C$22)) -> 100 | G22: =100*(max($D$16:$D$22)-D22)/(max($D$16:$D$22)-min($D$16:$D$22)) -> 27.402219 | H22: =100*(max($E$16:$E$22)-E22)/(max($E$16:$E$22)-min($E$16:$E$22)) -> 0 | I22: =0.4*F22+0.4*G22+0.2*H22 -> 50.960888 | J22: =IFERROR(__xludf.DUMMYFUNCTION("RANK.EQ(I22,filter(I:I,A:A=A22))"),4.0) -> 4
A23: Palm Oil Derivative | B23: AgroSource Intl. | C23: 454.16554 | D23: 299.51538 | E23: =countifs('Supply Chain'!D:D,A23,'Supply Chain'!B:B,B23,'Supply Chain'!J:J,2025,'Supply Chain'!K:K,"Y")/countifs('Supply Chain'!D:D,A23,'Supply Chain'!B:B,B23,'Supply Chain'!J:J,2025) -> 0.55384615 | F23: =100*(max($C$23:$C$29)-C23)/(max($C$23:$C$29)-min($C$23:$C$29)) -> 0 | G23: =100*(max($D$23:$D$29)-D23)/(max($D$23:$D$29)-min($D$23:$D$29)) -> 34.686629 | H23: =100*(max($E$23:$E$29)-E23)/(max($E$23:$E$29)-min($E$23:$E$29)) -> 0 | I23: =0.4*F23+0.4*G23+0.2*H23 -> 13.874652 | J23: =IFERROR(__xludf.DUMMYFUNCTION("RANK.EQ(I23,filter(I:I,A:A=A23))"),7.0) -> 7
A24: Palm Oil Derivative | B24: BioFeedstock Ltd. | C24: 452.74214 | D24: 295.37143 | E24: =countifs('Supply Chain'!D:D,A24,'Supply Chain'!B:B,B24,'Supply Chain'!J:J,2025,'Supply Chain'!K:K,"Y")/countifs('Supply Chain'!D:D,A24,'Supply Chain'!B:B,B24,'Supply Chain'!J:J,2025) -> 0.54761905 | F24: =100*(max($C$23:$C$29)-C24)/(max($C$23:$C$29)-min($C$23:$C$29)) -> 6.4275674 | G24: =100*(max($D$23:$D$29)-D24)/(max($D$23:$D$29)-min($D$23:$D$29)) -> 49.95879 | H24: =100*(max($E$23:$E$29)-E24)/(max($E$23:$E$29)-min($E$23:$E$29)) -> 3.7092329 | I24: =0.4*F24+0.4*G24+0.2*H24 -> 23.296389 | J24: =IFERROR(__xludf.DUMMYFUNCTION("RANK.EQ(I24,filter(I:I,A:A=A24))"),6.0) -> 6
A25: Palm Oil Derivative | B25: EcoMaterials Co. | C25: 451.72102 | D25: 281.79322 | E25: =countifs('Supply Chain'!D:D,A25,'Supply Chain'!B:B,B25,'Supply Chain'!J:J,2025,'Supply Chain'!K:K,"Y")/countifs('Supply Chain'!D:D,A25,'Supply Chain'!B:B,B25,'Supply Chain'!J:J,2025) -> 0.42372881 | F25: =100*(max($C$23:$C$29)-C25)/(max($C$23:$C$29)-min($C$23:$C$29)) -> 11.038623 | G25: =100*(max($D$23:$D$29)-D25)/(max($D$23:$D$29)-min($D$23:$D$29)) -> 100 | H25: =100*(max($E$23:$E$29)-E25)/(max($E$23:$E$29)-min($E$23:$E$29)) -> 77.505586 | I25: =0.4*F25+0.4*G25+0.2*H25 -> 59.916566 | J25: =IFERROR(__xludf.DUMMYFUNCTION("RANK.EQ(I25,filter(I:I,A:A=A25))"),2.0) -> 2
A26: Palm Oil Derivative | B26: GreenFibre BV | C26: 444.91043 | D26: 295.87174 | E26: =countifs('Supply Chain'!D:D,A26,'Supply Chain'!B:B,B26,'Supply Chain'!J:J,2025,'Supply Chain'!K:K,"Y")/countifs('Supply Chain'!D:D,A26,'Supply Chain'!B:B,B26,'Supply Chain'!J:J,2025) -> 0.39130435 | F26: =100*(max($C$23:$C$29)-C26)/(max($C$23:$C$29)-min($C$23:$C$29)) -> 41.792881 | G26: =100*(max($D$23:$D$29)-D26)/(max($D$23:$D$29)-min($D$23:$D$29)) -> 48.114942 | H26: =100*(max($E$23:$E$29)-E26)/(max($E$23:$E$29)-min($E$23:$E$29)) -> 96.819516 | I26: =0.4*F26+0.4*G26+0.2*H26 -> 55.327032 | J26: =IFERROR(__xludf.DUMMYFUNCTION("RANK.EQ(I26,filter(I:I,A:A=A26))"),3.0) -> 3
A27: Palm Oil Derivative | B27: NaturInput GmbH | C27: 442.60807 | D27: 308.49123 | E27: =countifs('Supply Chain'!D:D,A27,'Supply Chain'!B:B,B27,'Supply Chain'!J:J,2025,'Supply Chain'!K:K,"Y")/countifs('Supply Chain'!D:D,A27,'Supply Chain'!B:B,B27,'Supply Chain'!J:J,2025) -> 0.38596491 | F27: =100*(max($C$23:$C$29)-C27)/(max($C$23:$C$29)-min($C$23:$C$29)) -> 52.189571 | G27: =100*(max($D$23:$D$29)-D27)/(max($D$23:$D$29)-min($D$23:$D$29)) -> 1.6070016 | H27: =100*(max($E$23:$E$29)-E27)/(max($E$23:$E$29)-min($E$23:$E$29)) -> 100 | I27: =0.4*F27+0.4*G27+0.2*H27 -> 41.518629 | J27: =IFERROR(__xludf.DUMMYFUNCTION("RANK.EQ(I27,filter(I:I,A:A=A27))"),4.0) -> 4
A28: Palm Oil Derivative | B28: PalmEco Corp | C28: 432.02037 | D28: 292.87037 | E28: =countifs('Supply Chain'!D:D,A28,'Supply Chain'!B:B,B28,'Supply Chain'!J:J,2025,'Supply Chain'!K:K,"Y")/countifs('Supply Chain'!D:D,A28,'Supply Chain'!B:B,B28,'Supply Chain'!J:J,2025) -> 0.44444444 | F28: =100*(max($C$23:$C$29)-C28)/(max($C$23:$C$29)-min($C$23:$C$29)) -> 100 | G28: =100*(max($D$23:$D$29)-D28)/(max($D$23:$D$29)-min($D$23:$D$29)) -> 59.176205 | H28: =100*(max($E$23:$E$29)-E28)/(max($E$23:$E$29)-min($E$23:$E$29)) -> 65.166131 | I28: =0.4*F28+0.4*G28+0.2*H28 -> 76.703708 | J28: =IFERROR(__xludf.DUMMYFUNCTION("RANK.EQ(I28,filter(I:I,A:A=A28))"),1.0) -> 1
A29: Palm Oil Derivative | B29: SustainSource Inc. | C29: 447.88491 | D29: 308.92727 | E29: =countifs('Supply Chain'!D:D,A29,'Supply Chain'!B:B,B29,'Supply Chain'!J:J,2025,'Supply Chain'!K:K,"Y")/countifs('Supply Chain'!D:D,A29,'Supply Chain'!B:B,B29,'Supply Chain'!J:J,2025) -> 0.4 | F29: =100*(max($C$23:$C$29)-C29)/(max($C$23:$C$29)-min($C$23:$C$29)) -> 28.361173 | G29: =100*(max($D$23:$D$29)-D29)/(max($D$23:$D$29)-min($D$23:$D$29)) -> 0 | H29: =100*(max($E$23:$E$29)-E29)/(max($E$23:$E$29)-min($E$23:$E$29)) -> 91.639871 | I29: =0.4*F29+0.4*G29+0.2*H29 -> 29.672443 | J29: =IFERROR(__xludf.DUMMYFUNCTION("RANK.EQ(I29,filter(I:I,A:A=A29))"),5.0) -> 5
A30: Soy Protein Extract | B30: AgroSource Intl. | C30: 459.79053 | D30: 285.74561 | E30: =countifs('Supply Chain'!D:D,A30,'Supply Chain'!B:B,B30,'Supply Chain'!J:J,2025,'Supply Chain'!K:K,"Y")/countifs('Supply Chain'!D:D,A30,'Supply Chain'!B:B,B30,'Supply Chain'!J:J,2025) -> 0.40350877 | F30: =100*(max($C$30:$C$36)-C30)/(max($C$30:$C$36)-min($C$30:$C$36)) -> 44.873116 | G30: =100*(max($D$30:$D$36)-D30)/(max($D$30:$D$36)-min($D$30:$D$36)) -> 69.672615 | H30: =100*(max($E$30:$E$36)-E30)/(max($E$30:$E$36)-min($E$30:$E$36)) -> 100 | I30: =0.4*F30+0.4*G30+0.2*H30 -> 65.818292 | J30: =IFERROR(__xludf.DUMMYFUNCTION("RANK.EQ(I30,filter(I:I,A:A=A30))"),3.0) -> 3
A31: Soy Protein Extract | B31: BioFeedstock Ltd. | C31: 474.79661 | D31: 287.63929 | E31: =countifs('Supply Chain'!D:D,A31,'Supply Chain'!B:B,B31,'Supply Chain'!J:J,2025,'Supply Chain'!K:K,"Y")/countifs('Supply Chain'!D:D,A31,'Supply Chain'!B:B,B31,'Supply Chain'!J:J,2025) -> 0.5 | F31: =100*(max($C$30:$C$36)-C31)/(max($C$30:$C$36)-min($C$30:$C$36)) -> 12.259445 | G31: =100*(max($D$30:$D$36)-D31)/(max($D$30:$D$36)-min($D$30:$D$36)) -> 64.082284 | H31: =100*(max($E$30:$E$36)-E31)/(max($E$30:$E$36)-min($E$30:$E$36)) -> 34.897959 | I31: =0.4*F31+0.4*G31+0.2*H31 -> 37.516283 | J31: =IFERROR(__xludf.DUMMYFUNCTION("RANK.EQ(I31,filter(I:I,A:A=A31))"),4.0) -> 4
A32: Soy Protein Extract | B32: EcoMaterials Co. | C32: 441.51379 | D32: 309.34655 | E32: =countifs('Supply Chain'!D:D,A32,'Supply Chain'!B:B,B32,'Supply Chain'!J:J,2025,'Supply Chain'!K:K,"Y")/countifs('Supply Chain'!D:D,A32,'Supply Chain'!B:B,B32,'Supply Chain'!J:J,2025) -> 0.55172414 | F32: =100*(max($C$30:$C$36)-C32)/(max($C$30:$C$36)-min($C$30:$C$36)) -> 84.595104 | G32: =100*(max($D$30:$D$36)-D32)/(max($D$30:$D$36)-min($D$30:$D$36)) -> 0 | H32: =100*(max($E$30:$E$36)-E32)/(max($E$30:$E$36)-min($E$30:$E$36)) -> 0 | I32: =0.4*F32+0.4*G32+0.2*H32 -> 33.838042 | J32: =IFERROR(__xludf.DUMMYFUNCTION("RANK.EQ(I32,filter(I:I,A:A=A32))"),5.0) -> 5
A33: Soy Protein Extract | B33: GreenFibre BV | C33: 480.43738 | D33: 302.53607 | E33: =countifs('Supply Chain'!D:D,A33,'Supply Chain'!B:B,B33,'Supply Chain'!J:J,2025,'Supply Chain'!K:K,"Y")/countifs('Supply Chain'!D:D,A33,'Supply Chain'!B:B,B33,'Supply Chain'!J:J,2025) -> 0.45901639 | F33: =100*(max($C$30:$C$36)-C33)/(max($C$30:$C$36)-min($C$30:$C$36)) -> 0 | G33: =100*(max($D$30:$D$36)-D33)/(max($D$30:$D$36)-min($D$30:$D$36)) -> 20.105319 | H33: =100*(max($E$30:$E$36)-E33)/(max($E$30:$E$36)-min($E$30:$E$36)) -> 62.549348 | I33: =0.4*F33+0.4*G33+0.2*H33 -> 20.551997 | J33: =IFERROR(__xludf.DUMMYFUNCTION("RANK.EQ(I33,filter(I:I,A:A=A33))"),7.0) -> 7
A34: Soy Protein Extract | B34: NaturInput GmbH | C34: 474.96576 | D34: 308.82203 | E34: =countifs('Supply Chain'!D:D,A34,'Supply Chain'!B:B,B34,'Supply Chain'!J:J,2025,'Supply Chain'!K:K,"Y")/countifs('Supply Chain'!D:D,A34,'Supply Chain'!B:B,B34,'Supply Chain'!J:J,2025) -> 0.42372881 | F34: =100*(max($C$30:$C$36)-C34)/(max($C$30:$C$36)-min($C$30:$C$36)) -> 11.891808 | G34: =100*(max($D$30:$D$36)-D34)/(max($D$30:$D$36)-min($D$30:$D$36)) -> 1.5484355 | H34: =100*(max($E$30:$E$36)-E34)/(max($E$30:$E$36)-min($E$30:$E$36)) -> 86.357662 | I34: =0.4*F34+0.4*G34+0.2*H34 -> 22.64763 | J34: =IFERROR(__xludf.DUMMYFUNCTION("RANK.EQ(I34,filter(I:I,A:A=A34))"),6.0) -> 6
A35: Soy Protein Extract | B35: PalmEco Corp | C35: 445.27924 | D35: 285.37727 | E35: =countifs('Supply Chain'!D:D,A35,'Supply Chain'!B:B,B35,'Supply Chain'!J:J,2025,'Supply Chain'!K:K,"Y")/countifs('Supply Chain'!D:D,A35,'Supply Chain'!B:B,B35,'Supply Chain'!J:J,2025) -> 0.45454545 | F35: =100*(max($C$30:$C$36)-C35)/(max($C$30:$C$36)-min($C$30:$C$36)) -> 76.411414 | G35: =100*(max($D$30:$D$36)-D35)/(max($D$30:$D$36)-min($D$30:$D$36)) -> 70.76 | H35: =100*(max($E$30:$E$36)-E35)/(max($E$30:$E$36)-min($E$30:$E$36)) -> 65.565863 | I35: =0.4*F35+0.4*G35+0.2*H35 -> 71.981738 | J35: =IFERROR(__xludf.DUMMYFUNCTION("RANK.EQ(I35,filter(I:I,A:A=A35))"),2.0) -> 2
A36: Soy Protein Extract | B36: SustainSource Inc. | C36: 434.42575 | D36: 275.4725 | E36: =countifs('Supply Chain'!D:D,A36,'Supply Chain'!B:B,B36,'Supply Chain'!J:J,2025,'Supply Chain'!K:K,"Y")/countifs('Supply Chain'!D:D,A36,'Supply Chain'!B:B,B36,'Supply Chain'!J:J,2025) -> 0.5 | F36: =100*(max($C$30:$C$36)-C36)/(max($C$30:$C$36)-min($C$30:$C$36)) -> 100 | G36: =100*(max($D$30:$D$36)-D36)/(max($D$30:$D$36)-min($D$30:$D$36)) -> 100 | H36: =100*(max($E$30:$E$36)-E36)/(max($E$30:$E$36)-min($E$30:$E$36)) -> 34.897959 | I36: =0.4*F36+0.4*G36+0.2*H36 -> 86.979592 | J36: =IFERROR(__xludf.DUMMYFUNCTION("RANK.EQ(I36,filter(I:I,A:A=A36))"),1.0) -> 1
A37: Sugarcane Fiber | B37: AgroSource Intl. | C37: 452.96944 | D37: 284.46111 | E37: =countifs('Supply Chain'!D:D,A37,'Supply Chain'!B:B,B37,'Supply Chain'!J:J,2025,'Supply Chain'!K:K,"Y")/countifs('Supply Chain'!D:D,A37,'Supply Chain'!B:B,B37,'Supply Chain'!J:J,2025) -> 0.5 | F37: =100*(max($C$37:$C$43)-C37)/(max($C$37:$C$43)-min($C$37:$C$43)) -> 55.629972 | G37: =100*(max($D$37:$D$43)-D37)/(max($D$37:$D$43)-min($D$37:$D$43)) -> 100 | H37: =100*(max($E$37:$E$43)-E37)/(max($E$37:$E$43)-min($E$37:$E$43)) -> 47.727273 | I37: =0.4*F37+0.4*G37+0.2*H37 -> 71.797443 | J37: =IFERROR(__xludf.DUMMYFUNCTION("RANK.EQ(I37,filter(I:I,A:A=A37))"),1.0) -> 1
A38: Sugarcane Fiber | B38: BioFeedstock Ltd. | C38: 466.75 | D38: 302.81458 | E38: =countifs('Supply Chain'!D:D,A38,'Supply Chain'!B:B,B38,'Supply Chain'!J:J,2025,'Supply Chain'!K:K,"Y")/countifs('Supply Chain'!D:D,A38,'Supply Chain'!B:B,B38,'Supply Chain'!J:J,2025) -> 0.52083333 | F38: =100*(max($C$37:$C$43)-C38)/(max($C$37:$C$43)-min($C$37:$C$43)) -> 0 | G38: =100*(max($D$37:$D$43)-D38)/(max($D$37:$D$43)-min($D$37:$D$43)) -> 33.047806 | H38: =100*(max($E$37:$E$43)-E38)/(max($E$37:$E$43)-min($E$37:$E$43)) -> 32.481061 | I38: =0.4*F38+0.4*G38+0.2*H38 -> 19.715335 | J38: =IFERROR(__xludf.DUMMYFUNCTION("RANK.EQ(I38,filter(I:I,A:A=A38))"),6.0) -> 6
A39: Sugarcane Fiber | B39: EcoMaterials Co. | C39: 459.58455 | D39: 293.26061 | E39: =countifs('Supply Chain'!D:D,A39,'Supply Chain'!B:B,B39,'Supply Chain'!J:J,2025,'Supply Chain'!K:K,"Y")/countifs('Supply Chain'!D:D,A39,'Supply Chain'!B:B,B39,'Supply Chain'!J:J,2025) -> 0.51515152 | F39: =100*(max($C$37:$C$43)-C39)/(max($C$37:$C$43)-min($C$37:$C$43)) -> 28.925832 | G39: =100*(max($D$37:$D$43)-D39)/(max($D$37:$D$43)-min($D$37:$D$43)) -> 67.900053 | H39: =100*(max($E$37:$E$43)-E39)/(max($E$37:$E$43)-min($E$37:$E$43)) -> 36.639118 | I39: =0.4*F39+0.4*G39+0.2*H39 -> 46.058178 | J39: =IFERROR(__xludf.DUMMYFUNCTION("RANK.EQ(I39,filter(I:I,A:A=A39))"),5.0) -> 5
A40: Sugarcane Fiber | B40: GreenFibre BV | C40: 441.97818 | D40: 306.97121 | E40: =countifs('Supply Chain'!D:D,A40,'Supply Chain'!B:B,B40,'Supply Chain'!J:J,2025,'Supply Chain'!K:K,"Y")/countifs('Supply Chain'!D:D,A40,'Supply Chain'!B:B,B40,'Supply Chain'!J:J,2025) -> 0.48484848 | F40: =100*(max($C$37:$C$43)-C40)/(max($C$37:$C$43)-min($C$37:$C$43)) -> 100 | G40: =100*(max($D$37:$D$43)-D40)/(max($D$37:$D$43)-min($D$37:$D$43)) -> 17.884713 | H40: =100*(max($E$37:$E$43)-E40)/(max($E$37:$E$43)-min($E$37:$E$43)) -> 58.815427 | I40: =0.4*F40+0.4*G40+0.2*H40 -> 58.916971 | J40: =IFERROR(__xludf.DUMMYFUNCTION("RANK.EQ(I40,filter(I:I,A:A=A40))"),2.0) -> 2
...
